DEBUG:google.auth.transport.requests:Making request: POST https://oauth2.googleapis.com/token
DEBUG:urllib3.connectionpool:Starting new HTTPS connection (1): oauth2.googleapis.com:443
DEBUG:urllib3.connectionpool:https://oauth2.googleapis.com:443 "POST /token HTTP/1.1" 200 None
WARNING:googleapiclient.discovery_cache:file_cache is unavailable when using oauth2client >= 4.0.0 or google-auth
Traceback (most recent call last):
  File "C:\Users\Asad Siddiqui\AppData\Local\Packages\PythonSoftwareFoundation.Python.3.8_qbz5n2kfra8p0\LocalCache\local-packages\Python38\site-packages\googleapiclient\discovery_cache\file_cache.py", line 33, in <module>
    from oauth2client.contrib.locked_file import LockedFile
ModuleNotFoundError: No module named 'oauth2client'

During handling of the above exception, another exception occurred:

Traceback (most recent call last):
  File "C:\Users\Asad Siddiqui\AppData\Local\Packages\PythonSoftwareFoundation.Python.3.8_qbz5n2kfra8p0\LocalCache\local-packages\Python38\site-packages\googleapiclient\discovery_cache\file_cache.py", line 37, in <module>
    from oauth2client.locked_file import LockedFile
ModuleNotFoundError: No module named 'oauth2client'

During handling of the above exception, another exception occurred:

Traceback (most recent call last):
  File "C:\Users\Asad Siddiqui\AppData\Local\Packages\PythonSoftwareFoundation.Python.3.8_qbz5n2kfra8p0\LocalCache\local-packages\Python38\site-packages\googleapiclient\discovery_cache\__init__.py", line 44, in autodetect
    from . import file_cache
  File "C:\Users\Asad Siddiqui\AppData\Local\Packages\PythonSoftwareFoundation.Python.3.8_qbz5n2kfra8p0\LocalCache\local-packages\Python38\site-packages\googleapiclient\discovery_cache\file_cache.py", line 40, in <module>
    raise ImportError(
ImportError: file_cache is unavailable when using oauth2client >= 4.0.0 or google-auth
DEBUG:googleapiclient.discovery:URL being requested: GET https://www.googleapis.com/discovery/v1/apis/calendar/v3/rest
DEBUG:urllib3.util.retry:Converted retries value: 3 -> Retry(total=3, connect=None, read=None, redirect=None, status=None)
DEBUG:googleapiclient.discovery:URL being requested: GET https://www.googleapis.com/calendar/v3/users/me/calendarList?alt=json
WARNING:googleapiclient.discovery_cache:file_cache is unavailable when using oauth2client >= 4.0.0 or google-auth
Traceback (most recent call last):
  File "C:\Users\Asad Siddiqui\AppData\Local\Packages\PythonSoftwareFoundation.Python.3.8_qbz5n2kfra8p0\LocalCache\local-packages\Python38\site-packages\googleapiclient\discovery_cache\file_cache.py", line 33, in <module>
    from oauth2client.contrib.locked_file import LockedFile
ModuleNotFoundError: No module named 'oauth2client'

During handling of the above exception, another exception occurred:

Traceback (most recent call last):
  File "C:\Users\Asad Siddiqui\AppData\Local\Packages\PythonSoftwareFoundation.Python.3.8_qbz5n2kfra8p0\LocalCache\local-packages\Python38\site-packages\googleapiclient\discovery_cache\file_cache.py", line 37, in <module>
    from oauth2client.locked_file import LockedFile
ModuleNotFoundError: No module named 'oauth2client'

During handling of the above exception, another exception occurred:

Traceback (most recent call last):
  File "C:\Users\Asad Siddiqui\AppData\Local\Packages\PythonSoftwareFoundation.Python.3.8_qbz5n2kfra8p0\LocalCache\local-packages\Python38\site-packages\googleapiclient\discovery_cache\__init__.py", line 44, in autodetect
    from . import file_cache
  File "C:\Users\Asad Siddiqui\AppData\Local\Packages\PythonSoftwareFoundation.Python.3.8_qbz5n2kfra8p0\LocalCache\local-packages\Python38\site-packages\googleapiclient\discovery_cache\file_cache.py", line 40, in <module>
    raise ImportError(
ImportError: file_cache is unavailable when using oauth2client >= 4.0.0 or google-auth
DEBUG:googleapiclient.discovery:URL being requested: GET https://www.googleapis.com/discovery/v1/apis/sheets/v4/rest
DEBUG:urllib3.connectionpool:Starting new HTTPS connection (1): www.googleapis.com:443
DEBUG:urllib3.connectionpool:https://www.googleapis.com:443 "GET /drive/v3/files?q=mimeType%3D%22application%2Fvnd.google-apps.spreadsheet%22+and+name+%3D+%22Nexus+Recording+Schedule+-+Master%22&pageSize=1000&supportsAllDrives=True&includeItemsFromAllDrives=True HTTP/1.1" 200 None
DEBUG:urllib3.connectionpool:Starting new HTTPS connection (1): sheets.googleapis.com:443
DEBUG:urllib3.connectionpool:https://sheets.googleapis.com:443 "GET /v4/spreadsheets/15-sqH2xXxN2Oq-VPR-Ei7u9aUIqImjEMFieo32gd1BQ?includeGridData=false HTTP/1.1" 200 None
DEBUG:googleapiclient.discovery:URL being requested: GET https://sheets.googleapis.com/v4/spreadsheets/15-sqH2xXxN2Oq-VPR-Ei7u9aUIqImjEMFieo32gd1BQ/values/2-Schedule%20Recording-Instructional%20Day%21A57%3AAA?alt=json
DEBUG:googleapiclient.discovery:URL being requested: GET https://sheets.googleapis.com/v4/spreadsheets/15-sqH2xXxN2Oq-VPR-Ei7u9aUIqImjEMFieo32gd1BQ/values/1-Approve%20Courses-Instructors-DropDown%20Menus%21N2%3AO79?alt=json
DEBUG:googleapiclient.discovery:URL being requested: GET https://sheets.googleapis.com/v4/spreadsheets/15-sqH2xXxN2Oq-VPR-Ei7u9aUIqImjEMFieo32gd1BQ/values/1-Approve%20Courses-Instructors-DropDown%20Menus%21AG2%3AAH16?alt=json
DEBUG:urllib3.connectionpool:https://sheets.googleapis.com:443 "PUT /v4/spreadsheets/15-sqH2xXxN2Oq-VPR-Ei7u9aUIqImjEMFieo32gd1BQ/values/%272-Schedule%20Recording-Instructional%20Day%27%21Z57?valueInputOption=USER_ENTERED HTTP/1.1" 200 None
DEBUG:urllib3.connectionpool:https://sheets.googleapis.com:443 "PUT /v4/spreadsheets/15-sqH2xXxN2Oq-VPR-Ei7u9aUIqImjEMFieo32gd1BQ/values/%272-Schedule%20Recording-Instructional%20Day%27%21Z58?valueInputOption=USER_ENTERED HTTP/1.1" 200 None
DEBUG:urllib3.connectionpool:https://sheets.googleapis.com:443 "PUT /v4/spreadsheets/15-sqH2xXxN2Oq-VPR-Ei7u9aUIqImjEMFieo32gd1BQ/values/%272-Schedule%20Recording-Instructional%20Day%27%21Z59?valueInputOption=USER_ENTERED HTTP/1.1" 200 None
DEBUG:urllib3.connectionpool:https://sheets.googleapis.com:443 "PUT /v4/spreadsheets/15-sqH2xXxN2Oq-VPR-Ei7u9aUIqImjEMFieo32gd1BQ/values/%272-Schedule%20Recording-Instructional%20Day%27%21Z60?valueInputOption=USER_ENTERED HTTP/1.1" 200 None
DEBUG:urllib3.connectionpool:https://sheets.googleapis.com:443 "PUT /v4/spreadsheets/15-sqH2xXxN2Oq-VPR-Ei7u9aUIqImjEMFieo32gd1BQ/values/%272-Schedule%20Recording-Instructional%20Day%27%21Z61?valueInputOption=USER_ENTERED HTTP/1.1" 200 None
DEBUG:urllib3.connectionpool:https://sheets.googleapis.com:443 "PUT /v4/spreadsheets/15-sqH2xXxN2Oq-VPR-Ei7u9aUIqImjEMFieo32gd1BQ/values/%272-Schedule%20Recording-Instructional%20Day%27%21Z62?valueInputOption=USER_ENTERED HTTP/1.1" 200 None
DEBUG:urllib3.connectionpool:https://sheets.googleapis.com:443 "PUT /v4/spreadsheets/15-sqH2xXxN2Oq-VPR-Ei7u9aUIqImjEMFieo32gd1BQ/values/%272-Schedule%20Recording-Instructional%20Day%27%21Z63?valueInputOption=USER_ENTERED HTTP/1.1" 200 None
DEBUG:urllib3.connectionpool:https://sheets.googleapis.com:443 "PUT /v4/spreadsheets/15-sqH2xXxN2Oq-VPR-Ei7u9aUIqImjEMFieo32gd1BQ/values/%272-Schedule%20Recording-Instructional%20Day%27%21Z64?valueInputOption=USER_ENTERED HTTP/1.1" 200 None
DEBUG:urllib3.connectionpool:https://sheets.googleapis.com:443 "PUT /v4/spreadsheets/15-sqH2xXxN2Oq-VPR-Ei7u9aUIqImjEMFieo32gd1BQ/values/%272-Schedule%20Recording-Instructional%20Day%27%21Z65?valueInputOption=USER_ENTERED HTTP/1.1" 200 None
DEBUG:urllib3.connectionpool:https://sheets.googleapis.com:443 "PUT /v4/spreadsheets/15-sqH2xXxN2Oq-VPR-Ei7u9aUIqImjEMFieo32gd1BQ/values/%272-Schedule%20Recording-Instructional%20Day%27%21Z66?valueInputOption=USER_ENTERED HTTP/1.1" 200 None
DEBUG:urllib3.connectionpool:https://sheets.googleapis.com:443 "PUT /v4/spreadsheets/15-sqH2xXxN2Oq-VPR-Ei7u9aUIqImjEMFieo32gd1BQ/values/%272-Schedule%20Recording-Instructional%20Day%27%21Z67?valueInputOption=USER_ENTERED HTTP/1.1" 200 None
DEBUG:urllib3.connectionpool:https://sheets.googleapis.com:443 "PUT /v4/spreadsheets/15-sqH2xXxN2Oq-VPR-Ei7u9aUIqImjEMFieo32gd1BQ/values/%272-Schedule%20Recording-Instructional%20Day%27%21Z68?valueInputOption=USER_ENTERED HTTP/1.1" 200 None
WARNING:googleapiclient.discovery_cache:file_cache is unavailable when using oauth2client >= 4.0.0 or google-auth
Traceback (most recent call last):
  File "C:\Users\Asad Siddiqui\AppData\Local\Packages\PythonSoftwareFoundation.Python.3.8_qbz5n2kfra8p0\LocalCache\local-packages\Python38\site-packages\googleapiclient\discovery_cache\file_cache.py", line 33, in <module>
    from oauth2client.contrib.locked_file import LockedFile
ModuleNotFoundError: No module named 'oauth2client'

During handling of the above exception, another exception occurred:

Traceback (most recent call last):
  File "C:\Users\Asad Siddiqui\AppData\Local\Packages\PythonSoftwareFoundation.Python.3.8_qbz5n2kfra8p0\LocalCache\local-packages\Python38\site-packages\googleapiclient\discovery_cache\file_cache.py", line 37, in <module>
    from oauth2client.locked_file import LockedFile
ModuleNotFoundError: No module named 'oauth2client'

During handling of the above exception, another exception occurred:

Traceback (most recent call last):
  File "C:\Users\Asad Siddiqui\AppData\Local\Packages\PythonSoftwareFoundation.Python.3.8_qbz5n2kfra8p0\LocalCache\local-packages\Python38\site-packages\googleapiclient\discovery_cache\__init__.py", line 44, in autodetect
    from . import file_cache
  File "C:\Users\Asad Siddiqui\AppData\Local\Packages\PythonSoftwareFoundation.Python.3.8_qbz5n2kfra8p0\LocalCache\local-packages\Python38\site-packages\googleapiclient\discovery_cache\file_cache.py", line 40, in <module>
    raise ImportError(
ImportError: file_cache is unavailable when using oauth2client >= 4.0.0 or google-auth
DEBUG:googleapiclient.discovery:URL being requested: GET https://www.googleapis.com/discovery/v1/apis/calendar/v3/rest
DEBUG:urllib3.util.retry:Converted retries value: 3 -> Retry(total=3, connect=None, read=None, redirect=None, status=None)
DEBUG:googleapiclient.discovery:URL being requested: GET https://www.googleapis.com/calendar/v3/users/me/calendarList?alt=json
WARNING:googleapiclient.discovery_cache:file_cache is unavailable when using oauth2client >= 4.0.0 or google-auth
Traceback (most recent call last):
  File "C:\Users\Asad Siddiqui\AppData\Local\Packages\PythonSoftwareFoundation.Python.3.8_qbz5n2kfra8p0\LocalCache\local-packages\Python38\site-packages\googleapiclient\discovery_cache\file_cache.py", line 33, in <module>
    from oauth2client.contrib.locked_file import LockedFile
ModuleNotFoundError: No module named 'oauth2client'

During handling of the above exception, another exception occurred:

Traceback (most recent call last):
  File "C:\Users\Asad Siddiqui\AppData\Local\Packages\PythonSoftwareFoundation.Python.3.8_qbz5n2kfra8p0\LocalCache\local-packages\Python38\site-packages\googleapiclient\discovery_cache\file_cache.py", line 37, in <module>
    from oauth2client.locked_file import LockedFile
ModuleNotFoundError: No module named 'oauth2client'

During handling of the above exception, another exception occurred:

Traceback (most recent call last):
  File "C:\Users\Asad Siddiqui\AppData\Local\Packages\PythonSoftwareFoundation.Python.3.8_qbz5n2kfra8p0\LocalCache\local-packages\Python38\site-packages\googleapiclient\discovery_cache\__init__.py", line 44, in autodetect
    from . import file_cache
  File "C:\Users\Asad Siddiqui\AppData\Local\Packages\PythonSoftwareFoundation.Python.3.8_qbz5n2kfra8p0\LocalCache\local-packages\Python38\site-packages\googleapiclient\discovery_cache\file_cache.py", line 40, in <module>
    raise ImportError(
ImportError: file_cache is unavailable when using oauth2client >= 4.0.0 or google-auth
DEBUG:googleapiclient.discovery:URL being requested: GET https://www.googleapis.com/discovery/v1/apis/sheets/v4/rest
DEBUG:urllib3.connectionpool:Starting new HTTPS connection (1): www.googleapis.com:443
DEBUG:urllib3.connectionpool:https://www.googleapis.com:443 "GET /drive/v3/files?q=mimeType%3D%22application%2Fvnd.google-apps.spreadsheet%22+and+name+%3D+%22Nexus+Recording+Schedule+-+Master%22&pageSize=1000&supportsAllDrives=True&includeItemsFromAllDrives=True HTTP/1.1" 200 None
DEBUG:urllib3.connectionpool:Starting new HTTPS connection (1): sheets.googleapis.com:443
DEBUG:urllib3.connectionpool:https://sheets.googleapis.com:443 "GET /v4/spreadsheets/15-sqH2xXxN2Oq-VPR-Ei7u9aUIqImjEMFieo32gd1BQ?includeGridData=false HTTP/1.1" 200 None
DEBUG:googleapiclient.discovery:URL being requested: GET https://sheets.googleapis.com/v4/spreadsheets/15-sqH2xXxN2Oq-VPR-Ei7u9aUIqImjEMFieo32gd1BQ/values/2-Schedule%20Recording-Instructional%20Day%21A57%3AAA?alt=json
DEBUG:googleapiclient.discovery:URL being requested: GET https://sheets.googleapis.com/v4/spreadsheets/15-sqH2xXxN2Oq-VPR-Ei7u9aUIqImjEMFieo32gd1BQ/values/1-Approve%20Courses-Instructors-DropDown%20Menus%21N2%3AO79?alt=json
DEBUG:googleapiclient.discovery:URL being requested: GET https://sheets.googleapis.com/v4/spreadsheets/15-sqH2xXxN2Oq-VPR-Ei7u9aUIqImjEMFieo32gd1BQ/values/1-Approve%20Courses-Instructors-DropDown%20Menus%21AG2%3AAH16?alt=json
DEBUG:urllib3.connectionpool:https://sheets.googleapis.com:443 "PUT /v4/spreadsheets/15-sqH2xXxN2Oq-VPR-Ei7u9aUIqImjEMFieo32gd1BQ/values/%272-Schedule%20Recording-Instructional%20Day%27%21Z73?valueInputOption=USER_ENTERED HTTP/1.1" 200 None
WARNING:googleapiclient.discovery_cache:file_cache is unavailable when using oauth2client >= 4.0.0 or google-auth
Traceback (most recent call last):
  File "C:\Users\the real sauce boss\AppData\Local\Programs\Python\Python37-32\lib\site-packages\googleapiclient\discovery_cache\file_cache.py", line 33, in <module>
    from oauth2client.contrib.locked_file import LockedFile
ModuleNotFoundError: No module named 'oauth2client'

During handling of the above exception, another exception occurred:

Traceback (most recent call last):
  File "C:\Users\the real sauce boss\AppData\Local\Programs\Python\Python37-32\lib\site-packages\googleapiclient\discovery_cache\file_cache.py", line 37, in <module>
    from oauth2client.locked_file import LockedFile
ModuleNotFoundError: No module named 'oauth2client'

During handling of the above exception, another exception occurred:

Traceback (most recent call last):
  File "C:\Users\the real sauce boss\AppData\Local\Programs\Python\Python37-32\lib\site-packages\googleapiclient\discovery_cache\__init__.py", line 44, in autodetect
    from . import file_cache
  File "C:\Users\the real sauce boss\AppData\Local\Programs\Python\Python37-32\lib\site-packages\googleapiclient\discovery_cache\file_cache.py", line 41, in <module>
    "file_cache is unavailable when using oauth2client >= 4.0.0 or google-auth"
ImportError: file_cache is unavailable when using oauth2client >= 4.0.0 or google-auth
DEBUG:googleapiclient.discovery:URL being requested: GET https://www.googleapis.com/discovery/v1/apis/calendar/v3/rest
DEBUG:urllib3.util.retry:Converted retries value: 3 -> Retry(total=3, connect=None, read=None, redirect=None, status=None)
DEBUG:googleapiclient.discovery:URL being requested: GET https://www.googleapis.com/calendar/v3/users/me/calendarList?alt=json
WARNING:googleapiclient.discovery_cache:file_cache is unavailable when using oauth2client >= 4.0.0 or google-auth
Traceback (most recent call last):
  File "C:\Users\the real sauce boss\AppData\Local\Programs\Python\Python37-32\lib\site-packages\googleapiclient\discovery_cache\file_cache.py", line 33, in <module>
    from oauth2client.contrib.locked_file import LockedFile
ModuleNotFoundError: No module named 'oauth2client'

During handling of the above exception, another exception occurred:

Traceback (most recent call last):
  File "C:\Users\the real sauce boss\AppData\Local\Programs\Python\Python37-32\lib\site-packages\googleapiclient\discovery_cache\file_cache.py", line 37, in <module>
    from oauth2client.locked_file import LockedFile
ModuleNotFoundError: No module named 'oauth2client'

During handling of the above exception, another exception occurred:

Traceback (most recent call last):
  File "C:\Users\the real sauce boss\AppData\Local\Programs\Python\Python37-32\lib\site-packages\googleapiclient\discovery_cache\__init__.py", line 44, in autodetect
    from . import file_cache
  File "C:\Users\the real sauce boss\AppData\Local\Programs\Python\Python37-32\lib\site-packages\googleapiclient\discovery_cache\file_cache.py", line 41, in <module>
    "file_cache is unavailable when using oauth2client >= 4.0.0 or google-auth"
ImportError: file_cache is unavailable when using oauth2client >= 4.0.0 or google-auth
DEBUG:googleapiclient.discovery:URL being requested: GET https://www.googleapis.com/discovery/v1/apis/sheets/v4/rest
DEBUG:urllib3.connectionpool:Starting new HTTPS connection (1): www.googleapis.com:443
DEBUG:urllib3.connectionpool:https://www.googleapis.com:443 "GET /drive/v3/files?q=mimeType%3D%22application%2Fvnd.google-apps.spreadsheet%22+and+name+%3D+%22Nexus+Recording+Schedule+-+Master%22&pageSize=1000&supportsAllDrives=True&includeItemsFromAllDrives=True HTTP/1.1" 200 None
DEBUG:urllib3.connectionpool:Starting new HTTPS connection (1): sheets.googleapis.com:443
DEBUG:urllib3.connectionpool:https://sheets.googleapis.com:443 "GET /v4/spreadsheets/15-sqH2xXxN2Oq-VPR-Ei7u9aUIqImjEMFieo32gd1BQ?includeGridData=false HTTP/1.1" 200 None
DEBUG:googleapiclient.discovery:URL being requested: GET https://sheets.googleapis.com/v4/spreadsheets/15-sqH2xXxN2Oq-VPR-Ei7u9aUIqImjEMFieo32gd1BQ/values/2-Schedule%20Recording-Instructional%20Day%21A57%3AAA?alt=json
DEBUG:googleapiclient.discovery:URL being requested: GET https://sheets.googleapis.com/v4/spreadsheets/15-sqH2xXxN2Oq-VPR-Ei7u9aUIqImjEMFieo32gd1BQ/values/1-Approve%20Courses-Instructors-DropDown%20Menus%21N2%3AO79?alt=json
DEBUG:googleapiclient.discovery:URL being requested: GET https://sheets.googleapis.com/v4/spreadsheets/15-sqH2xXxN2Oq-VPR-Ei7u9aUIqImjEMFieo32gd1BQ/values/1-Approve%20Courses-Instructors-DropDown%20Menus%21AG2%3AAH16?alt=json
WARNING:googleapiclient.discovery_cache:file_cache is unavailable when using oauth2client >= 4.0.0 or google-auth
Traceback (most recent call last):
  File "C:\Users\the real sauce boss\AppData\Local\Programs\Python\Python37-32\lib\site-packages\googleapiclient\discovery_cache\file_cache.py", line 33, in <module>
    from oauth2client.contrib.locked_file import LockedFile
ModuleNotFoundError: No module named 'oauth2client'

During handling of the above exception, another exception occurred:

Traceback (most recent call last):
  File "C:\Users\the real sauce boss\AppData\Local\Programs\Python\Python37-32\lib\site-packages\googleapiclient\discovery_cache\file_cache.py", line 37, in <module>
    from oauth2client.locked_file import LockedFile
ModuleNotFoundError: No module named 'oauth2client'

During handling of the above exception, another exception occurred:

Traceback (most recent call last):
  File "C:\Users\the real sauce boss\AppData\Local\Programs\Python\Python37-32\lib\site-packages\googleapiclient\discovery_cache\__init__.py", line 44, in autodetect
    from . import file_cache
  File "C:\Users\the real sauce boss\AppData\Local\Programs\Python\Python37-32\lib\site-packages\googleapiclient\discovery_cache\file_cache.py", line 41, in <module>
    "file_cache is unavailable when using oauth2client >= 4.0.0 or google-auth"
ImportError: file_cache is unavailable when using oauth2client >= 4.0.0 or google-auth
DEBUG:googleapiclient.discovery:URL being requested: GET https://www.googleapis.com/discovery/v1/apis/calendar/v3/rest
DEBUG:urllib3.util.retry:Converted retries value: 3 -> Retry(total=3, connect=None, read=None, redirect=None, status=None)
DEBUG:googleapiclient.discovery:URL being requested: GET https://www.googleapis.com/calendar/v3/users/me/calendarList?alt=json
WARNING:googleapiclient.discovery_cache:file_cache is unavailable when using oauth2client >= 4.0.0 or google-auth
Traceback (most recent call last):
  File "C:\Users\the real sauce boss\AppData\Local\Programs\Python\Python37-32\lib\site-packages\googleapiclient\discovery_cache\file_cache.py", line 33, in <module>
    from oauth2client.contrib.locked_file import LockedFile
ModuleNotFoundError: No module named 'oauth2client'

During handling of the above exception, another exception occurred:

Traceback (most recent call last):
  File "C:\Users\the real sauce boss\AppData\Local\Programs\Python\Python37-32\lib\site-packages\googleapiclient\discovery_cache\file_cache.py", line 37, in <module>
    from oauth2client.locked_file import LockedFile
ModuleNotFoundError: No module named 'oauth2client'

During handling of the above exception, another exception occurred:

Traceback (most recent call last):
  File "C:\Users\the real sauce boss\AppData\Local\Programs\Python\Python37-32\lib\site-packages\googleapiclient\discovery_cache\__init__.py", line 44, in autodetect
    from . import file_cache
  File "C:\Users\the real sauce boss\AppData\Local\Programs\Python\Python37-32\lib\site-packages\googleapiclient\discovery_cache\file_cache.py", line 41, in <module>
    "file_cache is unavailable when using oauth2client >= 4.0.0 or google-auth"
ImportError: file_cache is unavailable when using oauth2client >= 4.0.0 or google-auth
DEBUG:googleapiclient.discovery:URL being requested: GET https://www.googleapis.com/discovery/v1/apis/sheets/v4/rest
DEBUG:urllib3.connectionpool:Starting new HTTPS connection (1): www.googleapis.com:443
DEBUG:urllib3.connectionpool:https://www.googleapis.com:443 "GET /drive/v3/files?q=mimeType%3D%22application%2Fvnd.google-apps.spreadsheet%22+and+name+%3D+%22Nexus+Recording+Schedule+-+Master%22&pageSize=1000&supportsAllDrives=True&includeItemsFromAllDrives=True HTTP/1.1" 200 None
DEBUG:urllib3.connectionpool:Starting new HTTPS connection (1): sheets.googleapis.com:443
DEBUG:urllib3.connectionpool:https://sheets.googleapis.com:443 "GET /v4/spreadsheets/15-sqH2xXxN2Oq-VPR-Ei7u9aUIqImjEMFieo32gd1BQ?includeGridData=false HTTP/1.1" 200 None
DEBUG:googleapiclient.discovery:URL being requested: GET https://sheets.googleapis.com/v4/spreadsheets/15-sqH2xXxN2Oq-VPR-Ei7u9aUIqImjEMFieo32gd1BQ/values/2-Schedule%20Recording-Instructional%20Day%21A57%3AAA?alt=json
DEBUG:googleapiclient.discovery:URL being requested: GET https://sheets.googleapis.com/v4/spreadsheets/15-sqH2xXxN2Oq-VPR-Ei7u9aUIqImjEMFieo32gd1BQ/values/1-Approve%20Courses-Instructors-DropDown%20Menus%21N2%3AO79?alt=json
DEBUG:googleapiclient.discovery:URL being requested: GET https://sheets.googleapis.com/v4/spreadsheets/15-sqH2xXxN2Oq-VPR-Ei7u9aUIqImjEMFieo32gd1BQ/values/1-Approve%20Courses-Instructors-DropDown%20Menus%21AG2%3AAH16?alt=json
DEBUG:urllib3.connectionpool:https://sheets.googleapis.com:443 "PUT /v4/spreadsheets/15-sqH2xXxN2Oq-VPR-Ei7u9aUIqImjEMFieo32gd1BQ/values/%272-Schedule%20Recording-Instructional%20Day%27%21Z57?valueInputOption=USER_ENTERED HTTP/1.1" 200 None
DEBUG:urllib3.connectionpool:https://sheets.googleapis.com:443 "PUT /v4/spreadsheets/15-sqH2xXxN2Oq-VPR-Ei7u9aUIqImjEMFieo32gd1BQ/values/%272-Schedule%20Recording-Instructional%20Day%27%21Z58?valueInputOption=USER_ENTERED HTTP/1.1" 200 None
DEBUG:urllib3.connectionpool:https://sheets.googleapis.com:443 "PUT /v4/spreadsheets/15-sqH2xXxN2Oq-VPR-Ei7u9aUIqImjEMFieo32gd1BQ/values/%272-Schedule%20Recording-Instructional%20Day%27%21Z59?valueInputOption=USER_ENTERED HTTP/1.1" 200 None
DEBUG:urllib3.connectionpool:https://sheets.googleapis.com:443 "PUT /v4/spreadsheets/15-sqH2xXxN2Oq-VPR-Ei7u9aUIqImjEMFieo32gd1BQ/values/%272-Schedule%20Recording-Instructional%20Day%27%21Z60?valueInputOption=USER_ENTERED HTTP/1.1" 200 None
DEBUG:google.auth.transport.requests:Making request: POST https://oauth2.googleapis.com/token
DEBUG:urllib3.connectionpool:Starting new HTTPS connection (1): oauth2.googleapis.com:443
DEBUG:urllib3.connectionpool:https://oauth2.googleapis.com:443 "POST /token HTTP/1.1" 200 None
WARNING:googleapiclient.discovery_cache:file_cache is unavailable when using oauth2client >= 4.0.0 or google-auth
Traceback (most recent call last):
  File "C:\Users\the real sauce boss\AppData\Local\Programs\Python\Python37-32\lib\site-packages\googleapiclient\discovery_cache\file_cache.py", line 33, in <module>
    from oauth2client.contrib.locked_file import LockedFile
ModuleNotFoundError: No module named 'oauth2client'

During handling of the above exception, another exception occurred:

Traceback (most recent call last):
  File "C:\Users\the real sauce boss\AppData\Local\Programs\Python\Python37-32\lib\site-packages\googleapiclient\discovery_cache\file_cache.py", line 37, in <module>
    from oauth2client.locked_file import LockedFile
ModuleNotFoundError: No module named 'oauth2client'

During handling of the above exception, another exception occurred:

Traceback (most recent call last):
  File "C:\Users\the real sauce boss\AppData\Local\Programs\Python\Python37-32\lib\site-packages\googleapiclient\discovery_cache\__init__.py", line 44, in autodetect
    from . import file_cache
  File "C:\Users\the real sauce boss\AppData\Local\Programs\Python\Python37-32\lib\site-packages\googleapiclient\discovery_cache\file_cache.py", line 41, in <module>
    "file_cache is unavailable when using oauth2client >= 4.0.0 or google-auth"
ImportError: file_cache is unavailable when using oauth2client >= 4.0.0 or google-auth
DEBUG:googleapiclient.discovery:URL being requested: GET https://www.googleapis.com/discovery/v1/apis/calendar/v3/rest
DEBUG:urllib3.util.retry:Converted retries value: 3 -> Retry(total=3, connect=None, read=None, redirect=None, status=None)
DEBUG:googleapiclient.discovery:URL being requested: GET https://www.googleapis.com/calendar/v3/users/me/calendarList?alt=json
WARNING:googleapiclient.discovery_cache:file_cache is unavailable when using oauth2client >= 4.0.0 or google-auth
Traceback (most recent call last):
  File "C:\Users\the real sauce boss\AppData\Local\Programs\Python\Python37-32\lib\site-packages\googleapiclient\discovery_cache\file_cache.py", line 33, in <module>
    from oauth2client.contrib.locked_file import LockedFile
ModuleNotFoundError: No module named 'oauth2client'

During handling of the above exception, another exception occurred:

Traceback (most recent call last):
  File "C:\Users\the real sauce boss\AppData\Local\Programs\Python\Python37-32\lib\site-packages\googleapiclient\discovery_cache\file_cache.py", line 37, in <module>
    from oauth2client.locked_file import LockedFile
ModuleNotFoundError: No module named 'oauth2client'

During handling of the above exception, another exception occurred:

Traceback (most recent call last):
  File "C:\Users\the real sauce boss\AppData\Local\Programs\Python\Python37-32\lib\site-packages\googleapiclient\discovery_cache\__init__.py", line 44, in autodetect
    from . import file_cache
  File "C:\Users\the real sauce boss\AppData\Local\Programs\Python\Python37-32\lib\site-packages\googleapiclient\discovery_cache\file_cache.py", line 41, in <module>
    "file_cache is unavailable when using oauth2client >= 4.0.0 or google-auth"
ImportError: file_cache is unavailable when using oauth2client >= 4.0.0 or google-auth
DEBUG:googleapiclient.discovery:URL being requested: GET https://www.googleapis.com/discovery/v1/apis/sheets/v4/rest
DEBUG:urllib3.connectionpool:Starting new HTTPS connection (1): www.googleapis.com:443
DEBUG:urllib3.connectionpool:https://www.googleapis.com:443 "GET /drive/v3/files?q=mimeType%3D%22application%2Fvnd.google-apps.spreadsheet%22+and+name+%3D+%22Nexus+Recording+Schedule+-+Master%22&pageSize=1000&supportsAllDrives=True&includeItemsFromAllDrives=True HTTP/1.1" 200 None
DEBUG:urllib3.connectionpool:Starting new HTTPS connection (1): sheets.googleapis.com:443
DEBUG:urllib3.connectionpool:https://sheets.googleapis.com:443 "GET /v4/spreadsheets/15-sqH2xXxN2Oq-VPR-Ei7u9aUIqImjEMFieo32gd1BQ?includeGridData=false HTTP/1.1" 200 None
DEBUG:googleapiclient.discovery:URL being requested: GET https://sheets.googleapis.com/v4/spreadsheets/15-sqH2xXxN2Oq-VPR-Ei7u9aUIqImjEMFieo32gd1BQ/values/2-Schedule%20Recording-Instructional%20Day%21A57%3AAA?alt=json
DEBUG:googleapiclient.discovery:URL being requested: GET https://sheets.googleapis.com/v4/spreadsheets/15-sqH2xXxN2Oq-VPR-Ei7u9aUIqImjEMFieo32gd1BQ/values/1-Approve%20Courses-Instructors-DropDown%20Menus%21N2%3AO79?alt=json
DEBUG:googleapiclient.discovery:URL being requested: GET https://sheets.googleapis.com/v4/spreadsheets/15-sqH2xXxN2Oq-VPR-Ei7u9aUIqImjEMFieo32gd1BQ/values/1-Approve%20Courses-Instructors-DropDown%20Menus%21AG2%3AAH16?alt=json
DEBUG:urllib3.connectionpool:https://sheets.googleapis.com:443 "PUT /v4/spreadsheets/15-sqH2xXxN2Oq-VPR-Ei7u9aUIqImjEMFieo32gd1BQ/values/%272-Schedule%20Recording-Instructional%20Day%27%21Z74?valueInputOption=USER_ENTERED HTTP/1.1" 200 None
WARNING:googleapiclient.discovery_cache:file_cache is unavailable when using oauth2client >= 4.0.0 or google-auth
Traceback (most recent call last):
  File "C:\Users\the real sauce boss\AppData\Local\Programs\Python\Python37-32\lib\site-packages\googleapiclient\discovery_cache\file_cache.py", line 33, in <module>
    from oauth2client.contrib.locked_file import LockedFile
ModuleNotFoundError: No module named 'oauth2client'

During handling of the above exception, another exception occurred:

Traceback (most recent call last):
  File "C:\Users\the real sauce boss\AppData\Local\Programs\Python\Python37-32\lib\site-packages\googleapiclient\discovery_cache\file_cache.py", line 37, in <module>
    from oauth2client.locked_file import LockedFile
ModuleNotFoundError: No module named 'oauth2client'

During handling of the above exception, another exception occurred:

Traceback (most recent call last):
  File "C:\Users\the real sauce boss\AppData\Local\Programs\Python\Python37-32\lib\site-packages\googleapiclient\discovery_cache\__init__.py", line 44, in autodetect
    from . import file_cache
  File "C:\Users\the real sauce boss\AppData\Local\Programs\Python\Python37-32\lib\site-packages\googleapiclient\discovery_cache\file_cache.py", line 41, in <module>
    "file_cache is unavailable when using oauth2client >= 4.0.0 or google-auth"
ImportError: file_cache is unavailable when using oauth2client >= 4.0.0 or google-auth
DEBUG:googleapiclient.discovery:URL being requested: GET https://www.googleapis.com/discovery/v1/apis/calendar/v3/rest
DEBUG:urllib3.util.retry:Converted retries value: 3 -> Retry(total=3, connect=None, read=None, redirect=None, status=None)
DEBUG:googleapiclient.discovery:URL being requested: GET https://www.googleapis.com/calendar/v3/users/me/calendarList?alt=json
WARNING:googleapiclient.discovery_cache:file_cache is unavailable when using oauth2client >= 4.0.0 or google-auth
Traceback (most recent call last):
  File "C:\Users\the real sauce boss\AppData\Local\Programs\Python\Python37-32\lib\site-packages\googleapiclient\discovery_cache\file_cache.py", line 33, in <module>
    from oauth2client.contrib.locked_file import LockedFile
ModuleNotFoundError: No module named 'oauth2client'

During handling of the above exception, another exception occurred:

Traceback (most recent call last):
  File "C:\Users\the real sauce boss\AppData\Local\Programs\Python\Python37-32\lib\site-packages\googleapiclient\discovery_cache\file_cache.py", line 37, in <module>
    from oauth2client.locked_file import LockedFile
ModuleNotFoundError: No module named 'oauth2client'

During handling of the above exception, another exception occurred:

Traceback (most recent call last):
  File "C:\Users\the real sauce boss\AppData\Local\Programs\Python\Python37-32\lib\site-packages\googleapiclient\discovery_cache\__init__.py", line 44, in autodetect
    from . import file_cache
  File "C:\Users\the real sauce boss\AppData\Local\Programs\Python\Python37-32\lib\site-packages\googleapiclient\discovery_cache\file_cache.py", line 41, in <module>
    "file_cache is unavailable when using oauth2client >= 4.0.0 or google-auth"
ImportError: file_cache is unavailable when using oauth2client >= 4.0.0 or google-auth
DEBUG:googleapiclient.discovery:URL being requested: GET https://www.googleapis.com/discovery/v1/apis/calendar/v3/rest
DEBUG:urllib3.util.retry:Converted retries value: 3 -> Retry(total=3, connect=None, read=None, redirect=None, status=None)
DEBUG:googleapiclient.discovery:URL being requested: GET https://www.googleapis.com/calendar/v3/users/me/calendarList?alt=json
WARNING:googleapiclient.discovery_cache:file_cache is unavailable when using oauth2client >= 4.0.0 or google-auth
Traceback (most recent call last):
  File "C:\Users\the real sauce boss\AppData\Local\Programs\Python\Python37-32\lib\site-packages\googleapiclient\discovery_cache\file_cache.py", line 33, in <module>
    from oauth2client.contrib.locked_file import LockedFile
ModuleNotFoundError: No module named 'oauth2client'

During handling of the above exception, another exception occurred:

Traceback (most recent call last):
  File "C:\Users\the real sauce boss\AppData\Local\Programs\Python\Python37-32\lib\site-packages\googleapiclient\discovery_cache\file_cache.py", line 37, in <module>
    from oauth2client.locked_file import LockedFile
ModuleNotFoundError: No module named 'oauth2client'

During handling of the above exception, another exception occurred:

Traceback (most recent call last):
  File "C:\Users\the real sauce boss\AppData\Local\Programs\Python\Python37-32\lib\site-packages\googleapiclient\discovery_cache\__init__.py", line 44, in autodetect
    from . import file_cache
  File "C:\Users\the real sauce boss\AppData\Local\Programs\Python\Python37-32\lib\site-packages\googleapiclient\discovery_cache\file_cache.py", line 41, in <module>
    "file_cache is unavailable when using oauth2client >= 4.0.0 or google-auth"
ImportError: file_cache is unavailable when using oauth2client >= 4.0.0 or google-auth
DEBUG:googleapiclient.discovery:URL being requested: GET https://www.googleapis.com/discovery/v1/apis/calendar/v3/rest
DEBUG:urllib3.util.retry:Converted retries value: 3 -> Retry(total=3, connect=None, read=None, redirect=None, status=None)
DEBUG:googleapiclient.discovery:URL being requested: GET https://www.googleapis.com/calendar/v3/users/me/calendarList?alt=json
WARNING:googleapiclient.discovery_cache:file_cache is unavailable when using oauth2client >= 4.0.0 or google-auth
Traceback (most recent call last):
  File "C:\Users\the real sauce boss\AppData\Local\Programs\Python\Python37-32\lib\site-packages\googleapiclient\discovery_cache\file_cache.py", line 33, in <module>
    from oauth2client.contrib.locked_file import LockedFile
ModuleNotFoundError: No module named 'oauth2client'

During handling of the above exception, another exception occurred:

Traceback (most recent call last):
  File "C:\Users\the real sauce boss\AppData\Local\Programs\Python\Python37-32\lib\site-packages\googleapiclient\discovery_cache\file_cache.py", line 37, in <module>
    from oauth2client.locked_file import LockedFile
ModuleNotFoundError: No module named 'oauth2client'

During handling of the above exception, another exception occurred:

Traceback (most recent call last):
  File "C:\Users\the real sauce boss\AppData\Local\Programs\Python\Python37-32\lib\site-packages\googleapiclient\discovery_cache\__init__.py", line 44, in autodetect
    from . import file_cache
  File "C:\Users\the real sauce boss\AppData\Local\Programs\Python\Python37-32\lib\site-packages\googleapiclient\discovery_cache\file_cache.py", line 41, in <module>
    "file_cache is unavailable when using oauth2client >= 4.0.0 or google-auth"
ImportError: file_cache is unavailable when using oauth2client >= 4.0.0 or google-auth
DEBUG:googleapiclient.discovery:URL being requested: GET https://www.googleapis.com/discovery/v1/apis/calendar/v3/rest
DEBUG:urllib3.util.retry:Converted retries value: 3 -> Retry(total=3, connect=None, read=None, redirect=None, status=None)
DEBUG:googleapiclient.discovery:URL being requested: GET https://www.googleapis.com/calendar/v3/users/me/calendarList?alt=json
WARNING:googleapiclient.discovery_cache:file_cache is unavailable when using oauth2client >= 4.0.0 or google-auth
Traceback (most recent call last):
  File "C:\Users\the real sauce boss\AppData\Local\Programs\Python\Python37-32\lib\site-packages\googleapiclient\discovery_cache\file_cache.py", line 33, in <module>
    from oauth2client.contrib.locked_file import LockedFile
ModuleNotFoundError: No module named 'oauth2client'

During handling of the above exception, another exception occurred:

Traceback (most recent call last):
  File "C:\Users\the real sauce boss\AppData\Local\Programs\Python\Python37-32\lib\site-packages\googleapiclient\discovery_cache\file_cache.py", line 37, in <module>
    from oauth2client.locked_file import LockedFile
ModuleNotFoundError: No module named 'oauth2client'

During handling of the above exception, another exception occurred:

Traceback (most recent call last):
  File "C:\Users\the real sauce boss\AppData\Local\Programs\Python\Python37-32\lib\site-packages\googleapiclient\discovery_cache\__init__.py", line 44, in autodetect
    from . import file_cache
  File "C:\Users\the real sauce boss\AppData\Local\Programs\Python\Python37-32\lib\site-packages\googleapiclient\discovery_cache\file_cache.py", line 41, in <module>
    "file_cache is unavailable when using oauth2client >= 4.0.0 or google-auth"
ImportError: file_cache is unavailable when using oauth2client >= 4.0.0 or google-auth
DEBUG:googleapiclient.discovery:URL being requested: GET https://www.googleapis.com/discovery/v1/apis/calendar/v3/rest
DEBUG:urllib3.util.retry:Converted retries value: 3 -> Retry(total=3, connect=None, read=None, redirect=None, status=None)
DEBUG:googleapiclient.discovery:URL being requested: GET https://www.googleapis.com/calendar/v3/users/me/calendarList?alt=json
DEBUG:google.auth.transport.requests:Making request: POST https://oauth2.googleapis.com/token
DEBUG:urllib3.connectionpool:Starting new HTTPS connection (1): oauth2.googleapis.com:443
DEBUG:urllib3.connectionpool:https://oauth2.googleapis.com:443 "POST /token HTTP/1.1" 200 None
WARNING:googleapiclient.discovery_cache:file_cache is unavailable when using oauth2client >= 4.0.0 or google-auth
Traceback (most recent call last):
  File "C:\Users\Asad Siddiqui\AppData\Local\Packages\PythonSoftwareFoundation.Python.3.8_qbz5n2kfra8p0\LocalCache\local-packages\Python38\site-packages\googleapiclient\discovery_cache\file_cache.py", line 33, in <module>
    from oauth2client.contrib.locked_file import LockedFile
ModuleNotFoundError: No module named 'oauth2client'

During handling of the above exception, another exception occurred:

Traceback (most recent call last):
  File "C:\Users\Asad Siddiqui\AppData\Local\Packages\PythonSoftwareFoundation.Python.3.8_qbz5n2kfra8p0\LocalCache\local-packages\Python38\site-packages\googleapiclient\discovery_cache\file_cache.py", line 37, in <module>
    from oauth2client.locked_file import LockedFile
ModuleNotFoundError: No module named 'oauth2client'

During handling of the above exception, another exception occurred:

Traceback (most recent call last):
  File "C:\Users\Asad Siddiqui\AppData\Local\Packages\PythonSoftwareFoundation.Python.3.8_qbz5n2kfra8p0\LocalCache\local-packages\Python38\site-packages\googleapiclient\discovery_cache\__init__.py", line 44, in autodetect
    from . import file_cache
  File "C:\Users\Asad Siddiqui\AppData\Local\Packages\PythonSoftwareFoundation.Python.3.8_qbz5n2kfra8p0\LocalCache\local-packages\Python38\site-packages\googleapiclient\discovery_cache\file_cache.py", line 40, in <module>
    raise ImportError(
ImportError: file_cache is unavailable when using oauth2client >= 4.0.0 or google-auth
DEBUG:googleapiclient.discovery:URL being requested: GET https://www.googleapis.com/discovery/v1/apis/calendar/v3/rest
DEBUG:urllib3.util.retry:Converted retries value: 3 -> Retry(total=3, connect=None, read=None, redirect=None, status=None)
DEBUG:googleapiclient.discovery:URL being requested: GET https://www.googleapis.com/calendar/v3/users/me/calendarList?alt=json
DEBUG:google.auth.transport.requests:Making request: POST https://oauth2.googleapis.com/token
DEBUG:urllib3.connectionpool:Starting new HTTPS connection (1): oauth2.googleapis.com:443
DEBUG:urllib3.connectionpool:https://oauth2.googleapis.com:443 "POST /token HTTP/1.1" 200 None
WARNING:googleapiclient.discovery_cache:file_cache is unavailable when using oauth2client >= 4.0.0 or google-auth
Traceback (most recent call last):
  File "C:\Users\the real sauce boss\AppData\Local\Programs\Python\Python37-32\lib\site-packages\googleapiclient\discovery_cache\file_cache.py", line 33, in <module>
    from oauth2client.contrib.locked_file import LockedFile
ModuleNotFoundError: No module named 'oauth2client'

During handling of the above exception, another exception occurred:

Traceback (most recent call last):
  File "C:\Users\the real sauce boss\AppData\Local\Programs\Python\Python37-32\lib\site-packages\googleapiclient\discovery_cache\file_cache.py", line 37, in <module>
    from oauth2client.locked_file import LockedFile
ModuleNotFoundError: No module named 'oauth2client'

During handling of the above exception, another exception occurred:

Traceback (most recent call last):
  File "C:\Users\the real sauce boss\AppData\Local\Programs\Python\Python37-32\lib\site-packages\googleapiclient\discovery_cache\__init__.py", line 44, in autodetect
    from . import file_cache
  File "C:\Users\the real sauce boss\AppData\Local\Programs\Python\Python37-32\lib\site-packages\googleapiclient\discovery_cache\file_cache.py", line 41, in <module>
    "file_cache is unavailable when using oauth2client >= 4.0.0 or google-auth"
ImportError: file_cache is unavailable when using oauth2client >= 4.0.0 or google-auth
DEBUG:googleapiclient.discovery:URL being requested: GET https://www.googleapis.com/discovery/v1/apis/calendar/v3/rest
DEBUG:urllib3.util.retry:Converted retries value: 3 -> Retry(total=3, connect=None, read=None, redirect=None, status=None)
DEBUG:urllib3.connectionpool:Starting new HTTPS connection (1): www.googleapis.com:443
DEBUG:urllib3.connectionpool:https://www.googleapis.com:443 "GET /drive/v3/files?q=mimeType%3D%22application%2Fvnd.google-apps.spreadsheet%22+and+name+%3D+%22Nexus+Recording+Schedule+-+Master%22&pageSize=1000&supportsAllDrives=True&includeItemsFromAllDrives=True HTTP/1.1" 200 None
DEBUG:urllib3.connectionpool:Starting new HTTPS connection (1): sheets.googleapis.com:443
DEBUG:urllib3.connectionpool:https://sheets.googleapis.com:443 "GET /v4/spreadsheets/15-sqH2xXxN2Oq-VPR-Ei7u9aUIqImjEMFieo32gd1BQ?includeGridData=false HTTP/1.1" 200 None
DEBUG:googleapiclient.discovery:URL being requested: GET https://www.googleapis.com/calendar/v3/users/me/calendarList?alt=json
WARNING:googleapiclient.discovery_cache:file_cache is unavailable when using oauth2client >= 4.0.0 or google-auth
Traceback (most recent call last):
  File "C:\Users\the real sauce boss\AppData\Local\Programs\Python\Python37-32\lib\site-packages\googleapiclient\discovery_cache\file_cache.py", line 33, in <module>
    from oauth2client.contrib.locked_file import LockedFile
ModuleNotFoundError: No module named 'oauth2client'

During handling of the above exception, another exception occurred:

Traceback (most recent call last):
  File "C:\Users\the real sauce boss\AppData\Local\Programs\Python\Python37-32\lib\site-packages\googleapiclient\discovery_cache\file_cache.py", line 37, in <module>
    from oauth2client.locked_file import LockedFile
ModuleNotFoundError: No module named 'oauth2client'

During handling of the above exception, another exception occurred:

Traceback (most recent call last):
  File "C:\Users\the real sauce boss\AppData\Local\Programs\Python\Python37-32\lib\site-packages\googleapiclient\discovery_cache\__init__.py", line 44, in autodetect
    from . import file_cache
  File "C:\Users\the real sauce boss\AppData\Local\Programs\Python\Python37-32\lib\site-packages\googleapiclient\discovery_cache\file_cache.py", line 41, in <module>
    "file_cache is unavailable when using oauth2client >= 4.0.0 or google-auth"
ImportError: file_cache is unavailable when using oauth2client >= 4.0.0 or google-auth
DEBUG:googleapiclient.discovery:URL being requested: GET https://www.googleapis.com/discovery/v1/apis/sheets/v4/rest
WARNING:googleapiclient.discovery_cache:file_cache is unavailable when using oauth2client >= 4.0.0 or google-auth
Traceback (most recent call last):
  File "C:\Users\the real sauce boss\AppData\Local\Programs\Python\Python37-32\lib\site-packages\googleapiclient\discovery_cache\file_cache.py", line 33, in <module>
    from oauth2client.contrib.locked_file import LockedFile
ModuleNotFoundError: No module named 'oauth2client'

During handling of the above exception, another exception occurred:

Traceback (most recent call last):
  File "C:\Users\the real sauce boss\AppData\Local\Programs\Python\Python37-32\lib\site-packages\googleapiclient\discovery_cache\file_cache.py", line 37, in <module>
    from oauth2client.locked_file import LockedFile
ModuleNotFoundError: No module named 'oauth2client'

During handling of the above exception, another exception occurred:

Traceback (most recent call last):
  File "C:\Users\the real sauce boss\AppData\Local\Programs\Python\Python37-32\lib\site-packages\googleapiclient\discovery_cache\__init__.py", line 44, in autodetect
    from . import file_cache
  File "C:\Users\the real sauce boss\AppData\Local\Programs\Python\Python37-32\lib\site-packages\googleapiclient\discovery_cache\file_cache.py", line 41, in <module>
    "file_cache is unavailable when using oauth2client >= 4.0.0 or google-auth"
ImportError: file_cache is unavailable when using oauth2client >= 4.0.0 or google-auth
DEBUG:googleapiclient.discovery:URL being requested: GET https://www.googleapis.com/discovery/v1/apis/calendar/v3/rest
DEBUG:urllib3.util.retry:Converted retries value: 3 -> Retry(total=3, connect=None, read=None, redirect=None, status=None)
DEBUG:urllib3.connectionpool:Starting new HTTPS connection (1): www.googleapis.com:443
DEBUG:urllib3.connectionpool:https://www.googleapis.com:443 "GET /drive/v3/files?q=mimeType%3D%22application%2Fvnd.google-apps.spreadsheet%22+and+name+%3D+%22Nexus+Recording+Schedule+-+Master%22&pageSize=1000&supportsAllDrives=True&includeItemsFromAllDrives=True HTTP/1.1" 200 None
DEBUG:urllib3.connectionpool:Starting new HTTPS connection (1): sheets.googleapis.com:443
DEBUG:urllib3.connectionpool:https://sheets.googleapis.com:443 "GET /v4/spreadsheets/15-sqH2xXxN2Oq-VPR-Ei7u9aUIqImjEMFieo32gd1BQ?includeGridData=false HTTP/1.1" 200 None
DEBUG:googleapiclient.discovery:URL being requested: GET https://www.googleapis.com/calendar/v3/users/me/calendarList?alt=json
WARNING:googleapiclient.discovery_cache:file_cache is unavailable when using oauth2client >= 4.0.0 or google-auth
Traceback (most recent call last):
  File "C:\Users\the real sauce boss\AppData\Local\Programs\Python\Python37-32\lib\site-packages\googleapiclient\discovery_cache\file_cache.py", line 33, in <module>
    from oauth2client.contrib.locked_file import LockedFile
ModuleNotFoundError: No module named 'oauth2client'

During handling of the above exception, another exception occurred:

Traceback (most recent call last):
  File "C:\Users\the real sauce boss\AppData\Local\Programs\Python\Python37-32\lib\site-packages\googleapiclient\discovery_cache\file_cache.py", line 37, in <module>
    from oauth2client.locked_file import LockedFile
ModuleNotFoundError: No module named 'oauth2client'

During handling of the above exception, another exception occurred:

Traceback (most recent call last):
  File "C:\Users\the real sauce boss\AppData\Local\Programs\Python\Python37-32\lib\site-packages\googleapiclient\discovery_cache\__init__.py", line 44, in autodetect
    from . import file_cache
  File "C:\Users\the real sauce boss\AppData\Local\Programs\Python\Python37-32\lib\site-packages\googleapiclient\discovery_cache\file_cache.py", line 41, in <module>
    "file_cache is unavailable when using oauth2client >= 4.0.0 or google-auth"
ImportError: file_cache is unavailable when using oauth2client >= 4.0.0 or google-auth
DEBUG:googleapiclient.discovery:URL being requested: GET https://www.googleapis.com/discovery/v1/apis/sheets/v4/rest
DEBUG:googleapiclient.discovery:URL being requested: GET https://sheets.googleapis.com/v4/spreadsheets/15-sqH2xXxN2Oq-VPR-Ei7u9aUIqImjEMFieo32gd1BQ/values/2-Schedule%20Recording-Instructional%20Day%21A57%3AAA?alt=json
DEBUG:googleapiclient.discovery:URL being requested: GET https://sheets.googleapis.com/v4/spreadsheets/15-sqH2xXxN2Oq-VPR-Ei7u9aUIqImjEMFieo32gd1BQ/values/1-Approve%20Courses-Instructors-DropDown%20Menus%21N2%3AO79?alt=json
DEBUG:googleapiclient.discovery:URL being requested: GET https://sheets.googleapis.com/v4/spreadsheets/15-sqH2xXxN2Oq-VPR-Ei7u9aUIqImjEMFieo32gd1BQ/values/1-Approve%20Courses-Instructors-DropDown%20Menus%21AG2%3AAH16?alt=json
DEBUG:urllib3.connectionpool:https://sheets.googleapis.com:443 "PUT /v4/spreadsheets/15-sqH2xXxN2Oq-VPR-Ei7u9aUIqImjEMFieo32gd1BQ/values/%272-Schedule%20Recording-Instructional%20Day%27%21Z57?valueInputOption=USER_ENTERED HTTP/1.1" 200 None
DEBUG:urllib3.connectionpool:https://sheets.googleapis.com:443 "PUT /v4/spreadsheets/15-sqH2xXxN2Oq-VPR-Ei7u9aUIqImjEMFieo32gd1BQ/values/%272-Schedule%20Recording-Instructional%20Day%27%21Z59?valueInputOption=USER_ENTERED HTTP/1.1" 200 None
DEBUG:urllib3.connectionpool:https://sheets.googleapis.com:443 "PUT /v4/spreadsheets/15-sqH2xXxN2Oq-VPR-Ei7u9aUIqImjEMFieo32gd1BQ/values/%272-Schedule%20Recording-Instructional%20Day%27%21Z60?valueInputOption=USER_ENTERED HTTP/1.1" 200 None
WARNING:googleapiclient.discovery_cache:file_cache is unavailable when using oauth2client >= 4.0.0 or google-auth
Traceback (most recent call last):
  File "C:\Users\the real sauce boss\AppData\Local\Programs\Python\Python37-32\lib\site-packages\googleapiclient\discovery_cache\file_cache.py", line 33, in <module>
    from oauth2client.contrib.locked_file import LockedFile
ModuleNotFoundError: No module named 'oauth2client'

During handling of the above exception, another exception occurred:

Traceback (most recent call last):
  File "C:\Users\the real sauce boss\AppData\Local\Programs\Python\Python37-32\lib\site-packages\googleapiclient\discovery_cache\file_cache.py", line 37, in <module>
    from oauth2client.locked_file import LockedFile
ModuleNotFoundError: No module named 'oauth2client'

During handling of the above exception, another exception occurred:

Traceback (most recent call last):
  File "C:\Users\the real sauce boss\AppData\Local\Programs\Python\Python37-32\lib\site-packages\googleapiclient\discovery_cache\__init__.py", line 44, in autodetect
    from . import file_cache
  File "C:\Users\the real sauce boss\AppData\Local\Programs\Python\Python37-32\lib\site-packages\googleapiclient\discovery_cache\file_cache.py", line 41, in <module>
    "file_cache is unavailable when using oauth2client >= 4.0.0 or google-auth"
ImportError: file_cache is unavailable when using oauth2client >= 4.0.0 or google-auth
DEBUG:googleapiclient.discovery:URL being requested: GET https://www.googleapis.com/discovery/v1/apis/calendar/v3/rest
DEBUG:urllib3.util.retry:Converted retries value: 3 -> Retry(total=3, connect=None, read=None, redirect=None, status=None)
DEBUG:urllib3.connectionpool:Starting new HTTPS connection (1): www.googleapis.com:443
DEBUG:urllib3.connectionpool:https://www.googleapis.com:443 "GET /drive/v3/files?q=mimeType%3D%22application%2Fvnd.google-apps.spreadsheet%22+and+name+%3D+%22Nexus+Recording+Schedule+-+Master%22&pageSize=1000&supportsAllDrives=True&includeItemsFromAllDrives=True HTTP/1.1" 200 None
DEBUG:urllib3.connectionpool:Starting new HTTPS connection (1): sheets.googleapis.com:443
DEBUG:urllib3.connectionpool:https://sheets.googleapis.com:443 "GET /v4/spreadsheets/15-sqH2xXxN2Oq-VPR-Ei7u9aUIqImjEMFieo32gd1BQ?includeGridData=false HTTP/1.1" 200 None
DEBUG:googleapiclient.discovery:URL being requested: GET https://www.googleapis.com/calendar/v3/users/me/calendarList?alt=json
WARNING:googleapiclient.discovery_cache:file_cache is unavailable when using oauth2client >= 4.0.0 or google-auth
Traceback (most recent call last):
  File "C:\Users\the real sauce boss\AppData\Local\Programs\Python\Python37-32\lib\site-packages\googleapiclient\discovery_cache\file_cache.py", line 33, in <module>
    from oauth2client.contrib.locked_file import LockedFile
ModuleNotFoundError: No module named 'oauth2client'

During handling of the above exception, another exception occurred:

Traceback (most recent call last):
  File "C:\Users\the real sauce boss\AppData\Local\Programs\Python\Python37-32\lib\site-packages\googleapiclient\discovery_cache\file_cache.py", line 37, in <module>
    from oauth2client.locked_file import LockedFile
ModuleNotFoundError: No module named 'oauth2client'

During handling of the above exception, another exception occurred:

Traceback (most recent call last):
  File "C:\Users\the real sauce boss\AppData\Local\Programs\Python\Python37-32\lib\site-packages\googleapiclient\discovery_cache\__init__.py", line 44, in autodetect
    from . import file_cache
  File "C:\Users\the real sauce boss\AppData\Local\Programs\Python\Python37-32\lib\site-packages\googleapiclient\discovery_cache\file_cache.py", line 41, in <module>
    "file_cache is unavailable when using oauth2client >= 4.0.0 or google-auth"
ImportError: file_cache is unavailable when using oauth2client >= 4.0.0 or google-auth
DEBUG:googleapiclient.discovery:URL being requested: GET https://www.googleapis.com/discovery/v1/apis/sheets/v4/rest
DEBUG:googleapiclient.discovery:URL being requested: GET https://sheets.googleapis.com/v4/spreadsheets/15-sqH2xXxN2Oq-VPR-Ei7u9aUIqImjEMFieo32gd1BQ/values/2-Schedule%20Recording-Instructional%20Day%21A57%3AAA?alt=json
DEBUG:googleapiclient.discovery:URL being requested: GET https://sheets.googleapis.com/v4/spreadsheets/15-sqH2xXxN2Oq-VPR-Ei7u9aUIqImjEMFieo32gd1BQ/values/1-Approve%20Courses-Instructors-DropDown%20Menus%21N2%3AO79?alt=json
DEBUG:googleapiclient.discovery:URL being requested: GET https://sheets.googleapis.com/v4/spreadsheets/15-sqH2xXxN2Oq-VPR-Ei7u9aUIqImjEMFieo32gd1BQ/values/1-Approve%20Courses-Instructors-DropDown%20Menus%21AG2%3AAH16?alt=json
DEBUG:urllib3.connectionpool:https://sheets.googleapis.com:443 "PUT /v4/spreadsheets/15-sqH2xXxN2Oq-VPR-Ei7u9aUIqImjEMFieo32gd1BQ/values/%272-Schedule%20Recording-Instructional%20Day%27%21Z80?valueInputOption=USER_ENTERED HTTP/1.1" 200 None
WARNING:googleapiclient.discovery_cache:file_cache is unavailable when using oauth2client >= 4.0.0 or google-auth
Traceback (most recent call last):
  File "C:\Users\the real sauce boss\AppData\Local\Programs\Python\Python37-32\lib\site-packages\googleapiclient\discovery_cache\file_cache.py", line 33, in <module>
    from oauth2client.contrib.locked_file import LockedFile
ModuleNotFoundError: No module named 'oauth2client'

During handling of the above exception, another exception occurred:

Traceback (most recent call last):
  File "C:\Users\the real sauce boss\AppData\Local\Programs\Python\Python37-32\lib\site-packages\googleapiclient\discovery_cache\file_cache.py", line 37, in <module>
    from oauth2client.locked_file import LockedFile
ModuleNotFoundError: No module named 'oauth2client'

During handling of the above exception, another exception occurred:

Traceback (most recent call last):
  File "C:\Users\the real sauce boss\AppData\Local\Programs\Python\Python37-32\lib\site-packages\googleapiclient\discovery_cache\__init__.py", line 44, in autodetect
    from . import file_cache
  File "C:\Users\the real sauce boss\AppData\Local\Programs\Python\Python37-32\lib\site-packages\googleapiclient\discovery_cache\file_cache.py", line 41, in <module>
    "file_cache is unavailable when using oauth2client >= 4.0.0 or google-auth"
ImportError: file_cache is unavailable when using oauth2client >= 4.0.0 or google-auth
DEBUG:googleapiclient.discovery:URL being requested: GET https://www.googleapis.com/discovery/v1/apis/calendar/v3/rest
DEBUG:urllib3.util.retry:Converted retries value: 3 -> Retry(total=3, connect=None, read=None, redirect=None, status=None)
DEBUG:urllib3.connectionpool:Starting new HTTPS connection (1): www.googleapis.com:443
DEBUG:urllib3.connectionpool:https://www.googleapis.com:443 "GET /drive/v3/files?q=mimeType%3D%22application%2Fvnd.google-apps.spreadsheet%22+and+name+%3D+%22Nexus+Recording+Schedule+-+Master%22&pageSize=1000&supportsAllDrives=True&includeItemsFromAllDrives=True HTTP/1.1" 200 None
DEBUG:urllib3.connectionpool:Starting new HTTPS connection (1): sheets.googleapis.com:443
DEBUG:urllib3.connectionpool:https://sheets.googleapis.com:443 "GET /v4/spreadsheets/15-sqH2xXxN2Oq-VPR-Ei7u9aUIqImjEMFieo32gd1BQ?includeGridData=false HTTP/1.1" 200 None
DEBUG:googleapiclient.discovery:URL being requested: GET https://www.googleapis.com/calendar/v3/users/me/calendarList?alt=json
WARNING:googleapiclient.discovery_cache:file_cache is unavailable when using oauth2client >= 4.0.0 or google-auth
Traceback (most recent call last):
  File "C:\Users\the real sauce boss\AppData\Local\Programs\Python\Python37-32\lib\site-packages\googleapiclient\discovery_cache\file_cache.py", line 33, in <module>
    from oauth2client.contrib.locked_file import LockedFile
ModuleNotFoundError: No module named 'oauth2client'

During handling of the above exception, another exception occurred:

Traceback (most recent call last):
  File "C:\Users\the real sauce boss\AppData\Local\Programs\Python\Python37-32\lib\site-packages\googleapiclient\discovery_cache\file_cache.py", line 37, in <module>
    from oauth2client.locked_file import LockedFile
ModuleNotFoundError: No module named 'oauth2client'

During handling of the above exception, another exception occurred:

Traceback (most recent call last):
  File "C:\Users\the real sauce boss\AppData\Local\Programs\Python\Python37-32\lib\site-packages\googleapiclient\discovery_cache\__init__.py", line 44, in autodetect
    from . import file_cache
  File "C:\Users\the real sauce boss\AppData\Local\Programs\Python\Python37-32\lib\site-packages\googleapiclient\discovery_cache\file_cache.py", line 41, in <module>
    "file_cache is unavailable when using oauth2client >= 4.0.0 or google-auth"
ImportError: file_cache is unavailable when using oauth2client >= 4.0.0 or google-auth
DEBUG:googleapiclient.discovery:URL being requested: GET https://www.googleapis.com/discovery/v1/apis/sheets/v4/rest
DEBUG:googleapiclient.discovery:URL being requested: GET https://sheets.googleapis.com/v4/spreadsheets/15-sqH2xXxN2Oq-VPR-Ei7u9aUIqImjEMFieo32gd1BQ/values/2-Schedule%20Recording-Instructional%20Day%21A57%3AAA?alt=json
DEBUG:googleapiclient.discovery:URL being requested: GET https://sheets.googleapis.com/v4/spreadsheets/15-sqH2xXxN2Oq-VPR-Ei7u9aUIqImjEMFieo32gd1BQ/values/1-Approve%20Courses-Instructors-DropDown%20Menus%21N2%3AO79?alt=json
DEBUG:googleapiclient.discovery:URL being requested: GET https://sheets.googleapis.com/v4/spreadsheets/15-sqH2xXxN2Oq-VPR-Ei7u9aUIqImjEMFieo32gd1BQ/values/1-Approve%20Courses-Instructors-DropDown%20Menus%21AG2%3AAH16?alt=json
DEBUG:urllib3.connectionpool:https://sheets.googleapis.com:443 "PUT /v4/spreadsheets/15-sqH2xXxN2Oq-VPR-Ei7u9aUIqImjEMFieo32gd1BQ/values/%272-Schedule%20Recording-Instructional%20Day%27%21Z61?valueInputOption=USER_ENTERED HTTP/1.1" 200 None
DEBUG:urllib3.connectionpool:https://sheets.googleapis.com:443 "PUT /v4/spreadsheets/15-sqH2xXxN2Oq-VPR-Ei7u9aUIqImjEMFieo32gd1BQ/values/%272-Schedule%20Recording-Instructional%20Day%27%21Z62?valueInputOption=USER_ENTERED HTTP/1.1" 200 None
DEBUG:urllib3.connectionpool:https://sheets.googleapis.com:443 "PUT /v4/spreadsheets/15-sqH2xXxN2Oq-VPR-Ei7u9aUIqImjEMFieo32gd1BQ/values/%272-Schedule%20Recording-Instructional%20Day%27%21Z67?valueInputOption=USER_ENTERED HTTP/1.1" 200 None
DEBUG:urllib3.connectionpool:https://sheets.googleapis.com:443 "PUT /v4/spreadsheets/15-sqH2xXxN2Oq-VPR-Ei7u9aUIqImjEMFieo32gd1BQ/values/%272-Schedule%20Recording-Instructional%20Day%27%21Z68?valueInputOption=USER_ENTERED HTTP/1.1" 200 None
DEBUG:urllib3.connectionpool:https://sheets.googleapis.com:443 "PUT /v4/spreadsheets/15-sqH2xXxN2Oq-VPR-Ei7u9aUIqImjEMFieo32gd1BQ/values/%272-Schedule%20Recording-Instructional%20Day%27%21Z69?valueInputOption=USER_ENTERED HTTP/1.1" 200 None
DEBUG:urllib3.connectionpool:https://sheets.googleapis.com:443 "PUT /v4/spreadsheets/15-sqH2xXxN2Oq-VPR-Ei7u9aUIqImjEMFieo32gd1BQ/values/%272-Schedule%20Recording-Instructional%20Day%27%21Z70?valueInputOption=USER_ENTERED HTTP/1.1" 200 None
DEBUG:urllib3.connectionpool:https://sheets.googleapis.com:443 "PUT /v4/spreadsheets/15-sqH2xXxN2Oq-VPR-Ei7u9aUIqImjEMFieo32gd1BQ/values/%272-Schedule%20Recording-Instructional%20Day%27%21Z71?valueInputOption=USER_ENTERED HTTP/1.1" 200 None
DEBUG:urllib3.connectionpool:https://sheets.googleapis.com:443 "PUT /v4/spreadsheets/15-sqH2xXxN2Oq-VPR-Ei7u9aUIqImjEMFieo32gd1BQ/values/%272-Schedule%20Recording-Instructional%20Day%27%21Z72?valueInputOption=USER_ENTERED HTTP/1.1" 200 None
WARNING:googleapiclient.discovery_cache:file_cache is unavailable when using oauth2client >= 4.0.0 or google-auth
Traceback (most recent call last):
  File "C:\Users\the real sauce boss\AppData\Local\Programs\Python\Python37-32\lib\site-packages\googleapiclient\discovery_cache\file_cache.py", line 33, in <module>
    from oauth2client.contrib.locked_file import LockedFile
ModuleNotFoundError: No module named 'oauth2client'

During handling of the above exception, another exception occurred:

Traceback (most recent call last):
  File "C:\Users\the real sauce boss\AppData\Local\Programs\Python\Python37-32\lib\site-packages\googleapiclient\discovery_cache\file_cache.py", line 37, in <module>
    from oauth2client.locked_file import LockedFile
ModuleNotFoundError: No module named 'oauth2client'

During handling of the above exception, another exception occurred:

Traceback (most recent call last):
  File "C:\Users\the real sauce boss\AppData\Local\Programs\Python\Python37-32\lib\site-packages\googleapiclient\discovery_cache\__init__.py", line 44, in autodetect
    from . import file_cache
  File "C:\Users\the real sauce boss\AppData\Local\Programs\Python\Python37-32\lib\site-packages\googleapiclient\discovery_cache\file_cache.py", line 41, in <module>
    "file_cache is unavailable when using oauth2client >= 4.0.0 or google-auth"
ImportError: file_cache is unavailable when using oauth2client >= 4.0.0 or google-auth
DEBUG:googleapiclient.discovery:URL being requested: GET https://www.googleapis.com/discovery/v1/apis/calendar/v3/rest
DEBUG:urllib3.util.retry:Converted retries value: 3 -> Retry(total=3, connect=None, read=None, redirect=None, status=None)
DEBUG:urllib3.connectionpool:Starting new HTTPS connection (1): www.googleapis.com:443
DEBUG:urllib3.connectionpool:https://www.googleapis.com:443 "GET /drive/v3/files?q=mimeType%3D%22application%2Fvnd.google-apps.spreadsheet%22+and+name+%3D+%22Nexus+Recording+Schedule+-+Master%22&pageSize=1000&supportsAllDrives=True&includeItemsFromAllDrives=True HTTP/1.1" 200 None
DEBUG:urllib3.connectionpool:Starting new HTTPS connection (1): sheets.googleapis.com:443
DEBUG:urllib3.connectionpool:https://sheets.googleapis.com:443 "GET /v4/spreadsheets/15-sqH2xXxN2Oq-VPR-Ei7u9aUIqImjEMFieo32gd1BQ?includeGridData=false HTTP/1.1" 200 None
DEBUG:googleapiclient.discovery:URL being requested: GET https://www.googleapis.com/calendar/v3/users/me/calendarList?alt=json
WARNING:googleapiclient.discovery_cache:file_cache is unavailable when using oauth2client >= 4.0.0 or google-auth
Traceback (most recent call last):
  File "C:\Users\the real sauce boss\AppData\Local\Programs\Python\Python37-32\lib\site-packages\googleapiclient\discovery_cache\file_cache.py", line 33, in <module>
    from oauth2client.contrib.locked_file import LockedFile
ModuleNotFoundError: No module named 'oauth2client'

During handling of the above exception, another exception occurred:

Traceback (most recent call last):
  File "C:\Users\the real sauce boss\AppData\Local\Programs\Python\Python37-32\lib\site-packages\googleapiclient\discovery_cache\file_cache.py", line 37, in <module>
    from oauth2client.locked_file import LockedFile
ModuleNotFoundError: No module named 'oauth2client'

During handling of the above exception, another exception occurred:

Traceback (most recent call last):
  File "C:\Users\the real sauce boss\AppData\Local\Programs\Python\Python37-32\lib\site-packages\googleapiclient\discovery_cache\__init__.py", line 44, in autodetect
    from . import file_cache
  File "C:\Users\the real sauce boss\AppData\Local\Programs\Python\Python37-32\lib\site-packages\googleapiclient\discovery_cache\file_cache.py", line 41, in <module>
    "file_cache is unavailable when using oauth2client >= 4.0.0 or google-auth"
ImportError: file_cache is unavailable when using oauth2client >= 4.0.0 or google-auth
DEBUG:googleapiclient.discovery:URL being requested: GET https://www.googleapis.com/discovery/v1/apis/sheets/v4/rest
DEBUG:googleapiclient.discovery:URL being requested: GET https://sheets.googleapis.com/v4/spreadsheets/15-sqH2xXxN2Oq-VPR-Ei7u9aUIqImjEMFieo32gd1BQ/values/2-Schedule%20Recording-Instructional%20Day%21A57%3AAA?alt=json
DEBUG:googleapiclient.discovery:URL being requested: GET https://sheets.googleapis.com/v4/spreadsheets/15-sqH2xXxN2Oq-VPR-Ei7u9aUIqImjEMFieo32gd1BQ/values/1-Approve%20Courses-Instructors-DropDown%20Menus%21N2%3AO79?alt=json
DEBUG:googleapiclient.discovery:URL being requested: GET https://sheets.googleapis.com/v4/spreadsheets/15-sqH2xXxN2Oq-VPR-Ei7u9aUIqImjEMFieo32gd1BQ/values/1-Approve%20Courses-Instructors-DropDown%20Menus%21AG2%3AAH16?alt=json
WARNING:googleapiclient.discovery_cache:file_cache is unavailable when using oauth2client >= 4.0.0 or google-auth
Traceback (most recent call last):
  File "C:\Users\the real sauce boss\AppData\Local\Programs\Python\Python37-32\lib\site-packages\googleapiclient\discovery_cache\file_cache.py", line 33, in <module>
    from oauth2client.contrib.locked_file import LockedFile
ModuleNotFoundError: No module named 'oauth2client'

During handling of the above exception, another exception occurred:

Traceback (most recent call last):
  File "C:\Users\the real sauce boss\AppData\Local\Programs\Python\Python37-32\lib\site-packages\googleapiclient\discovery_cache\file_cache.py", line 37, in <module>
    from oauth2client.locked_file import LockedFile
ModuleNotFoundError: No module named 'oauth2client'

During handling of the above exception, another exception occurred:

Traceback (most recent call last):
  File "C:\Users\the real sauce boss\AppData\Local\Programs\Python\Python37-32\lib\site-packages\googleapiclient\discovery_cache\__init__.py", line 44, in autodetect
    from . import file_cache
  File "C:\Users\the real sauce boss\AppData\Local\Programs\Python\Python37-32\lib\site-packages\googleapiclient\discovery_cache\file_cache.py", line 41, in <module>
    "file_cache is unavailable when using oauth2client >= 4.0.0 or google-auth"
ImportError: file_cache is unavailable when using oauth2client >= 4.0.0 or google-auth
DEBUG:googleapiclient.discovery:URL being requested: GET https://www.googleapis.com/discovery/v1/apis/calendar/v3/rest
DEBUG:urllib3.util.retry:Converted retries value: 3 -> Retry(total=3, connect=None, read=None, redirect=None, status=None)
DEBUG:urllib3.connectionpool:Starting new HTTPS connection (1): www.googleapis.com:443
DEBUG:urllib3.connectionpool:https://www.googleapis.com:443 "GET /drive/v3/files?q=mimeType%3D%22application%2Fvnd.google-apps.spreadsheet%22+and+name+%3D+%22Nexus+Recording+Schedule+-+Master%22&pageSize=1000&supportsAllDrives=True&includeItemsFromAllDrives=True HTTP/1.1" 200 None
DEBUG:urllib3.connectionpool:Starting new HTTPS connection (1): sheets.googleapis.com:443
DEBUG:urllib3.connectionpool:https://sheets.googleapis.com:443 "GET /v4/spreadsheets/15-sqH2xXxN2Oq-VPR-Ei7u9aUIqImjEMFieo32gd1BQ?includeGridData=false HTTP/1.1" 200 None
DEBUG:googleapiclient.discovery:URL being requested: GET https://www.googleapis.com/calendar/v3/users/me/calendarList?alt=json
WARNING:googleapiclient.discovery_cache:file_cache is unavailable when using oauth2client >= 4.0.0 or google-auth
Traceback (most recent call last):
  File "C:\Users\the real sauce boss\AppData\Local\Programs\Python\Python37-32\lib\site-packages\googleapiclient\discovery_cache\file_cache.py", line 33, in <module>
    from oauth2client.contrib.locked_file import LockedFile
ModuleNotFoundError: No module named 'oauth2client'

During handling of the above exception, another exception occurred:

Traceback (most recent call last):
  File "C:\Users\the real sauce boss\AppData\Local\Programs\Python\Python37-32\lib\site-packages\googleapiclient\discovery_cache\file_cache.py", line 37, in <module>
    from oauth2client.locked_file import LockedFile
ModuleNotFoundError: No module named 'oauth2client'

During handling of the above exception, another exception occurred:

Traceback (most recent call last):
  File "C:\Users\the real sauce boss\AppData\Local\Programs\Python\Python37-32\lib\site-packages\googleapiclient\discovery_cache\__init__.py", line 44, in autodetect
    from . import file_cache
  File "C:\Users\the real sauce boss\AppData\Local\Programs\Python\Python37-32\lib\site-packages\googleapiclient\discovery_cache\file_cache.py", line 41, in <module>
    "file_cache is unavailable when using oauth2client >= 4.0.0 or google-auth"
ImportError: file_cache is unavailable when using oauth2client >= 4.0.0 or google-auth
DEBUG:googleapiclient.discovery:URL being requested: GET https://www.googleapis.com/discovery/v1/apis/sheets/v4/rest
DEBUG:googleapiclient.discovery:URL being requested: GET https://sheets.googleapis.com/v4/spreadsheets/15-sqH2xXxN2Oq-VPR-Ei7u9aUIqImjEMFieo32gd1BQ/values/2-Schedule%20Recording-Instructional%20Day%21A57%3AAA?alt=json
DEBUG:googleapiclient.discovery:URL being requested: GET https://sheets.googleapis.com/v4/spreadsheets/15-sqH2xXxN2Oq-VPR-Ei7u9aUIqImjEMFieo32gd1BQ/values/1-Approve%20Courses-Instructors-DropDown%20Menus%21N2%3AO79?alt=json
DEBUG:googleapiclient.discovery:URL being requested: GET https://sheets.googleapis.com/v4/spreadsheets/15-sqH2xXxN2Oq-VPR-Ei7u9aUIqImjEMFieo32gd1BQ/values/1-Approve%20Courses-Instructors-DropDown%20Menus%21AG2%3AAH16?alt=json
DEBUG:urllib3.connectionpool:https://sheets.googleapis.com:443 "PUT /v4/spreadsheets/15-sqH2xXxN2Oq-VPR-Ei7u9aUIqImjEMFieo32gd1BQ/values/%272-Schedule%20Recording-Instructional%20Day%27%21Z76?valueInputOption=USER_ENTERED HTTP/1.1" 200 None
DEBUG:requests_oauthlib.oauth2_session:Generated new state 8krXH4NKY3S0hlBxQPVQbIBRiKhe8j.
INFO:google_auth_oauthlib.flow:"GET /?state=8krXH4NKY3S0hlBxQPVQbIBRiKhe8j&code=4/2AFNTlCs2zvt-5vNVF0yqW8tLWMnPw-7AFGwReHXHFHpEhCvxGdepo5nwyOMIyQJC11Yef7TpffZa0ZaRfzOatE&scope=https://www.googleapis.com/auth/calendar%20https://www.googleapis.com/auth/spreadsheets%20https://www.googleapis.com/auth/drive HTTP/1.1" 200 65
DEBUG:requests_oauthlib.oauth2_session:Encoding `client_id` "684343053641-6o79kfodd569mo60qr90nnp3a9n3fqi9.apps.googleusercontent.com" with `client_secret` as Basic auth credentials.
DEBUG:requests_oauthlib.oauth2_session:Requesting url https://oauth2.googleapis.com/token using method POST.
DEBUG:requests_oauthlib.oauth2_session:Supplying headers {'Accept': 'application/json', 'Content-Type': 'application/x-www-form-urlencoded;charset=UTF-8'} and data {'grant_type': 'authorization_code', 'code': '4/2AFNTlCs2zvt-5vNVF0yqW8tLWMnPw-7AFGwReHXHFHpEhCvxGdepo5nwyOMIyQJC11Yef7TpffZa0ZaRfzOatE', 'redirect_uri': 'http://localhost:50830/'}
DEBUG:requests_oauthlib.oauth2_session:Passing through key word arguments {'timeout': None, 'auth': <requests.auth.HTTPBasicAuth object at 0x033A4E30>, 'verify': True, 'proxies': None}.
DEBUG:urllib3.connectionpool:Starting new HTTPS connection (1): oauth2.googleapis.com:443
DEBUG:urllib3.connectionpool:https://oauth2.googleapis.com:443 "POST /token HTTP/1.1" 200 None
DEBUG:requests_oauthlib.oauth2_session:Request to fetch token completed with status 200.
DEBUG:requests_oauthlib.oauth2_session:Request url was https://oauth2.googleapis.com/token
DEBUG:requests_oauthlib.oauth2_session:Request headers were {'User-Agent': 'python-requests/2.24.0', 'Accept-Encoding': 'gzip, deflate', 'Accept': 'application/json', 'Connection': 'keep-alive', 'Content-Type': 'application/x-www-form-urlencoded;charset=UTF-8', 'Content-Length': '173', 'Authorization': 'Basic Njg0MzQzMDUzNjQxLTZvNzlrZm9kZDU2OW1vNjBxcjkwbm5wM2E5bjNmcWk5LmFwcHMuZ29vZ2xldXNlcmNvbnRlbnQuY29tOkxMUFVkOFNVc25lU2NnOWdLeFpnbGtIYQ=='}
DEBUG:requests_oauthlib.oauth2_session:Request body was grant_type=authorization_code&code=4%2F2AFNTlCs2zvt-5vNVF0yqW8tLWMnPw-7AFGwReHXHFHpEhCvxGdepo5nwyOMIyQJC11Yef7TpffZa0ZaRfzOatE&redirect_uri=http%3A%2F%2Flocalhost%3A50830%2F
DEBUG:requests_oauthlib.oauth2_session:Response headers were {'Content-Type': 'application/json; charset=utf-8', 'Vary': 'Origin, X-Origin, Referer', 'Content-Encoding': 'gzip', 'Date': 'Fri, 17 Jul 2020 16:12:19 GMT', 'Server': 'scaffolding on HTTPServer2', 'Cache-Control': 'private', 'X-XSS-Protection': '0', 'X-Frame-Options': 'SAMEORIGIN', 'X-Content-Type-Options': 'nosniff', 'Alt-Svc': 'h3-29=":443"; ma=2592000,h3-27=":443"; ma=2592000,h3-25=":443"; ma=2592000,h3-T050=":443"; ma=2592000,h3-Q050=":443"; ma=2592000,h3-Q046=":443"; ma=2592000,h3-Q043=":443"; ma=2592000,quic=":443"; ma=2592000; v="46,43"', 'Transfer-Encoding': 'chunked'} and content {
  "access_token": "ya29.a0AfH6SMDxVTFtgyIjb7qO6NKlzFHGYhsPhERGDV1aTOr9OFsjBaMtdDMuSkTlpVAKNLZtQ17W8aeqcj_ise13XR93QSh7Rbt9WWhNfbYuwoA0RWbG9U7To-zZasb73S3f6O0tWHnwio_d7FCVaoXr93eaPpjGpiHtjR8",
  "expires_in": 3599,
  "refresh_token": "1//0fijfRiYzE4hKCgYIARAAGA8SNwF-L9Irf0uBDPwlFhK-UVMlGu_cnqkSHKTgAWOWseAuzewXxXYyU_Uo6-UCo2ffYM2SiaeF_E8",
  "scope": "https://www.googleapis.com/auth/drive https://www.googleapis.com/auth/spreadsheets https://www.googleapis.com/auth/calendar",
  "token_type": "Bearer"
}.
DEBUG:requests_oauthlib.oauth2_session:Invoking 0 token response hooks.
DEBUG:requests_oauthlib.oauth2_session:Obtained token {'access_token': 'ya29.a0AfH6SMDxVTFtgyIjb7qO6NKlzFHGYhsPhERGDV1aTOr9OFsjBaMtdDMuSkTlpVAKNLZtQ17W8aeqcj_ise13XR93QSh7Rbt9WWhNfbYuwoA0RWbG9U7To-zZasb73S3f6O0tWHnwio_d7FCVaoXr93eaPpjGpiHtjR8', 'expires_in': 3599, 'refresh_token': '1//0fijfRiYzE4hKCgYIARAAGA8SNwF-L9Irf0uBDPwlFhK-UVMlGu_cnqkSHKTgAWOWseAuzewXxXYyU_Uo6-UCo2ffYM2SiaeF_E8', 'scope': ['https://www.googleapis.com/auth/drive', 'https://www.googleapis.com/auth/spreadsheets', 'https://www.googleapis.com/auth/calendar'], 'token_type': 'Bearer', 'expires_at': 1595005939.0615585}.
WARNING:googleapiclient.discovery_cache:file_cache is unavailable when using oauth2client >= 4.0.0 or google-auth
Traceback (most recent call last):
  File "C:\Users\the real sauce boss\AppData\Local\Programs\Python\Python37-32\lib\site-packages\googleapiclient\discovery_cache\file_cache.py", line 33, in <module>
    from oauth2client.contrib.locked_file import LockedFile
ModuleNotFoundError: No module named 'oauth2client'

During handling of the above exception, another exception occurred:

Traceback (most recent call last):
  File "C:\Users\the real sauce boss\AppData\Local\Programs\Python\Python37-32\lib\site-packages\googleapiclient\discovery_cache\file_cache.py", line 37, in <module>
    from oauth2client.locked_file import LockedFile
ModuleNotFoundError: No module named 'oauth2client'

During handling of the above exception, another exception occurred:

Traceback (most recent call last):
  File "C:\Users\the real sauce boss\AppData\Local\Programs\Python\Python37-32\lib\site-packages\googleapiclient\discovery_cache\__init__.py", line 44, in autodetect
    from . import file_cache
  File "C:\Users\the real sauce boss\AppData\Local\Programs\Python\Python37-32\lib\site-packages\googleapiclient\discovery_cache\file_cache.py", line 41, in <module>
    "file_cache is unavailable when using oauth2client >= 4.0.0 or google-auth"
ImportError: file_cache is unavailable when using oauth2client >= 4.0.0 or google-auth
DEBUG:googleapiclient.discovery:URL being requested: GET https://www.googleapis.com/discovery/v1/apis/calendar/v3/rest
DEBUG:urllib3.util.retry:Converted retries value: 3 -> Retry(total=3, connect=None, read=None, redirect=None, status=None)
DEBUG:urllib3.connectionpool:Starting new HTTPS connection (1): www.googleapis.com:443
DEBUG:urllib3.connectionpool:https://www.googleapis.com:443 "GET /drive/v3/files?q=mimeType%3D%22application%2Fvnd.google-apps.spreadsheet%22+and+name+%3D+%22Nexus+Recording+Schedule+-+Master%22&pageSize=1000&supportsAllDrives=True&includeItemsFromAllDrives=True HTTP/1.1" 200 None
DEBUG:urllib3.connectionpool:Starting new HTTPS connection (1): sheets.googleapis.com:443
DEBUG:urllib3.connectionpool:https://sheets.googleapis.com:443 "GET /v4/spreadsheets/15-sqH2xXxN2Oq-VPR-Ei7u9aUIqImjEMFieo32gd1BQ?includeGridData=false HTTP/1.1" 200 None
DEBUG:googleapiclient.discovery:URL being requested: GET https://www.googleapis.com/calendar/v3/users/me/calendarList?alt=json
WARNING:googleapiclient.discovery_cache:file_cache is unavailable when using oauth2client >= 4.0.0 or google-auth
Traceback (most recent call last):
  File "C:\Users\the real sauce boss\AppData\Local\Programs\Python\Python37-32\lib\site-packages\googleapiclient\discovery_cache\file_cache.py", line 33, in <module>
    from oauth2client.contrib.locked_file import LockedFile
ModuleNotFoundError: No module named 'oauth2client'

During handling of the above exception, another exception occurred:

Traceback (most recent call last):
  File "C:\Users\the real sauce boss\AppData\Local\Programs\Python\Python37-32\lib\site-packages\googleapiclient\discovery_cache\file_cache.py", line 37, in <module>
    from oauth2client.locked_file import LockedFile
ModuleNotFoundError: No module named 'oauth2client'

During handling of the above exception, another exception occurred:

Traceback (most recent call last):
  File "C:\Users\the real sauce boss\AppData\Local\Programs\Python\Python37-32\lib\site-packages\googleapiclient\discovery_cache\__init__.py", line 44, in autodetect
    from . import file_cache
  File "C:\Users\the real sauce boss\AppData\Local\Programs\Python\Python37-32\lib\site-packages\googleapiclient\discovery_cache\file_cache.py", line 41, in <module>
    "file_cache is unavailable when using oauth2client >= 4.0.0 or google-auth"
ImportError: file_cache is unavailable when using oauth2client >= 4.0.0 or google-auth
DEBUG:googleapiclient.discovery:URL being requested: GET https://www.googleapis.com/discovery/v1/apis/sheets/v4/rest
DEBUG:google.auth.transport.requests:Making request: POST https://oauth2.googleapis.com/token
DEBUG:urllib3.connectionpool:Starting new HTTPS connection (1): oauth2.googleapis.com:443
DEBUG:urllib3.connectionpool:https://oauth2.googleapis.com:443 "POST /token HTTP/1.1" 200 None
WARNING:googleapiclient.discovery_cache:file_cache is unavailable when using oauth2client >= 4.0.0 or google-auth
Traceback (most recent call last):
  File "C:\Users\the real sauce boss\AppData\Local\Programs\Python\Python37-32\lib\site-packages\googleapiclient\discovery_cache\file_cache.py", line 33, in <module>
    from oauth2client.contrib.locked_file import LockedFile
ModuleNotFoundError: No module named 'oauth2client'

During handling of the above exception, another exception occurred:

Traceback (most recent call last):
  File "C:\Users\the real sauce boss\AppData\Local\Programs\Python\Python37-32\lib\site-packages\googleapiclient\discovery_cache\file_cache.py", line 37, in <module>
    from oauth2client.locked_file import LockedFile
ModuleNotFoundError: No module named 'oauth2client'

During handling of the above exception, another exception occurred:

Traceback (most recent call last):
  File "C:\Users\the real sauce boss\AppData\Local\Programs\Python\Python37-32\lib\site-packages\googleapiclient\discovery_cache\__init__.py", line 44, in autodetect
    from . import file_cache
  File "C:\Users\the real sauce boss\AppData\Local\Programs\Python\Python37-32\lib\site-packages\googleapiclient\discovery_cache\file_cache.py", line 41, in <module>
    "file_cache is unavailable when using oauth2client >= 4.0.0 or google-auth"
ImportError: file_cache is unavailable when using oauth2client >= 4.0.0 or google-auth
DEBUG:googleapiclient.discovery:URL being requested: GET https://www.googleapis.com/discovery/v1/apis/calendar/v3/rest
DEBUG:urllib3.util.retry:Converted retries value: 3 -> Retry(total=3, connect=None, read=None, redirect=None, status=None)
DEBUG:urllib3.connectionpool:Starting new HTTPS connection (1): www.googleapis.com:443
DEBUG:urllib3.connectionpool:https://www.googleapis.com:443 "GET /drive/v3/files?q=mimeType%3D%22application%2Fvnd.google-apps.spreadsheet%22+and+name+%3D+%22Nexus+Recording+Schedule+-+Master%22&pageSize=1000&supportsAllDrives=True&includeItemsFromAllDrives=True HTTP/1.1" 200 None
DEBUG:urllib3.connectionpool:Starting new HTTPS connection (1): sheets.googleapis.com:443
DEBUG:urllib3.connectionpool:https://sheets.googleapis.com:443 "GET /v4/spreadsheets/15-sqH2xXxN2Oq-VPR-Ei7u9aUIqImjEMFieo32gd1BQ?includeGridData=false HTTP/1.1" 200 None
DEBUG:googleapiclient.discovery:URL being requested: GET https://www.googleapis.com/calendar/v3/users/me/calendarList?alt=json
WARNING:googleapiclient.discovery_cache:file_cache is unavailable when using oauth2client >= 4.0.0 or google-auth
Traceback (most recent call last):
  File "C:\Users\the real sauce boss\AppData\Local\Programs\Python\Python37-32\lib\site-packages\googleapiclient\discovery_cache\file_cache.py", line 33, in <module>
    from oauth2client.contrib.locked_file import LockedFile
ModuleNotFoundError: No module named 'oauth2client'

During handling of the above exception, another exception occurred:

Traceback (most recent call last):
  File "C:\Users\the real sauce boss\AppData\Local\Programs\Python\Python37-32\lib\site-packages\googleapiclient\discovery_cache\file_cache.py", line 37, in <module>
    from oauth2client.locked_file import LockedFile
ModuleNotFoundError: No module named 'oauth2client'

During handling of the above exception, another exception occurred:

Traceback (most recent call last):
  File "C:\Users\the real sauce boss\AppData\Local\Programs\Python\Python37-32\lib\site-packages\googleapiclient\discovery_cache\__init__.py", line 44, in autodetect
    from . import file_cache
  File "C:\Users\the real sauce boss\AppData\Local\Programs\Python\Python37-32\lib\site-packages\googleapiclient\discovery_cache\file_cache.py", line 41, in <module>
    "file_cache is unavailable when using oauth2client >= 4.0.0 or google-auth"
ImportError: file_cache is unavailable when using oauth2client >= 4.0.0 or google-auth
DEBUG:googleapiclient.discovery:URL being requested: GET https://www.googleapis.com/discovery/v1/apis/sheets/v4/rest
DEBUG:googleapiclient.discovery:URL being requested: GET https://sheets.googleapis.com/v4/spreadsheets/15-sqH2xXxN2Oq-VPR-Ei7u9aUIqImjEMFieo32gd1BQ/values/2-Schedule%20Recording-Instructional%20Day%21A57%3AAA?alt=json
DEBUG:googleapiclient.discovery:URL being requested: GET https://sheets.googleapis.com/v4/spreadsheets/15-sqH2xXxN2Oq-VPR-Ei7u9aUIqImjEMFieo32gd1BQ/values/1-Approve%20Courses-Instructors-DropDown%20Menus%21N2%3AO79?alt=json
DEBUG:googleapiclient.discovery:URL being requested: GET https://sheets.googleapis.com/v4/spreadsheets/15-sqH2xXxN2Oq-VPR-Ei7u9aUIqImjEMFieo32gd1BQ/values/1-Approve%20Courses-Instructors-DropDown%20Menus%21AG2%3AAH16?alt=json
WARNING:googleapiclient.discovery_cache:file_cache is unavailable when using oauth2client >= 4.0.0 or google-auth
Traceback (most recent call last):
  File "C:\Users\the real sauce boss\AppData\Local\Programs\Python\Python37-32\lib\site-packages\googleapiclient\discovery_cache\file_cache.py", line 33, in <module>
    from oauth2client.contrib.locked_file import LockedFile
ModuleNotFoundError: No module named 'oauth2client'

During handling of the above exception, another exception occurred:

Traceback (most recent call last):
  File "C:\Users\the real sauce boss\AppData\Local\Programs\Python\Python37-32\lib\site-packages\googleapiclient\discovery_cache\file_cache.py", line 37, in <module>
    from oauth2client.locked_file import LockedFile
ModuleNotFoundError: No module named 'oauth2client'

During handling of the above exception, another exception occurred:

Traceback (most recent call last):
  File "C:\Users\the real sauce boss\AppData\Local\Programs\Python\Python37-32\lib\site-packages\googleapiclient\discovery_cache\__init__.py", line 44, in autodetect
    from . import file_cache
  File "C:\Users\the real sauce boss\AppData\Local\Programs\Python\Python37-32\lib\site-packages\googleapiclient\discovery_cache\file_cache.py", line 41, in <module>
    "file_cache is unavailable when using oauth2client >= 4.0.0 or google-auth"
ImportError: file_cache is unavailable when using oauth2client >= 4.0.0 or google-auth
DEBUG:googleapiclient.discovery:URL being requested: GET https://www.googleapis.com/discovery/v1/apis/calendar/v3/rest
DEBUG:urllib3.util.retry:Converted retries value: 3 -> Retry(total=3, connect=None, read=None, redirect=None, status=None)
DEBUG:urllib3.connectionpool:Starting new HTTPS connection (1): www.googleapis.com:443
DEBUG:urllib3.connectionpool:https://www.googleapis.com:443 "GET /drive/v3/files?q=mimeType%3D%22application%2Fvnd.google-apps.spreadsheet%22+and+name+%3D+%22Nexus+Recording+Schedule+-+Master%22&pageSize=1000&supportsAllDrives=True&includeItemsFromAllDrives=True HTTP/1.1" 200 None
DEBUG:urllib3.connectionpool:Starting new HTTPS connection (1): sheets.googleapis.com:443
DEBUG:urllib3.connectionpool:https://sheets.googleapis.com:443 "GET /v4/spreadsheets/15-sqH2xXxN2Oq-VPR-Ei7u9aUIqImjEMFieo32gd1BQ?includeGridData=false HTTP/1.1" 200 None
DEBUG:googleapiclient.discovery:URL being requested: GET https://www.googleapis.com/calendar/v3/users/me/calendarList?alt=json
WARNING:googleapiclient.discovery_cache:file_cache is unavailable when using oauth2client >= 4.0.0 or google-auth
Traceback (most recent call last):
  File "C:\Users\the real sauce boss\AppData\Local\Programs\Python\Python37-32\lib\site-packages\googleapiclient\discovery_cache\file_cache.py", line 33, in <module>
    from oauth2client.contrib.locked_file import LockedFile
ModuleNotFoundError: No module named 'oauth2client'

During handling of the above exception, another exception occurred:

Traceback (most recent call last):
  File "C:\Users\the real sauce boss\AppData\Local\Programs\Python\Python37-32\lib\site-packages\googleapiclient\discovery_cache\file_cache.py", line 37, in <module>
    from oauth2client.locked_file import LockedFile
ModuleNotFoundError: No module named 'oauth2client'

During handling of the above exception, another exception occurred:

Traceback (most recent call last):
  File "C:\Users\the real sauce boss\AppData\Local\Programs\Python\Python37-32\lib\site-packages\googleapiclient\discovery_cache\__init__.py", line 44, in autodetect
    from . import file_cache
  File "C:\Users\the real sauce boss\AppData\Local\Programs\Python\Python37-32\lib\site-packages\googleapiclient\discovery_cache\file_cache.py", line 41, in <module>
    "file_cache is unavailable when using oauth2client >= 4.0.0 or google-auth"
ImportError: file_cache is unavailable when using oauth2client >= 4.0.0 or google-auth
DEBUG:googleapiclient.discovery:URL being requested: GET https://www.googleapis.com/discovery/v1/apis/sheets/v4/rest
DEBUG:googleapiclient.discovery:URL being requested: GET https://sheets.googleapis.com/v4/spreadsheets/15-sqH2xXxN2Oq-VPR-Ei7u9aUIqImjEMFieo32gd1BQ/values/1-Approve%20Courses-Instructors-DropDown%20Menus%21N2%3AAN799?alt=json
WARNING:googleapiclient.discovery_cache:file_cache is unavailable when using oauth2client >= 4.0.0 or google-auth
Traceback (most recent call last):
  File "C:\Users\the real sauce boss\AppData\Local\Programs\Python\Python37-32\lib\site-packages\googleapiclient\discovery_cache\file_cache.py", line 33, in <module>
    from oauth2client.contrib.locked_file import LockedFile
ModuleNotFoundError: No module named 'oauth2client'

During handling of the above exception, another exception occurred:

Traceback (most recent call last):
  File "C:\Users\the real sauce boss\AppData\Local\Programs\Python\Python37-32\lib\site-packages\googleapiclient\discovery_cache\file_cache.py", line 37, in <module>
    from oauth2client.locked_file import LockedFile
ModuleNotFoundError: No module named 'oauth2client'

During handling of the above exception, another exception occurred:

Traceback (most recent call last):
  File "C:\Users\the real sauce boss\AppData\Local\Programs\Python\Python37-32\lib\site-packages\googleapiclient\discovery_cache\__init__.py", line 44, in autodetect
    from . import file_cache
  File "C:\Users\the real sauce boss\AppData\Local\Programs\Python\Python37-32\lib\site-packages\googleapiclient\discovery_cache\file_cache.py", line 41, in <module>
    "file_cache is unavailable when using oauth2client >= 4.0.0 or google-auth"
ImportError: file_cache is unavailable when using oauth2client >= 4.0.0 or google-auth
DEBUG:googleapiclient.discovery:URL being requested: GET https://www.googleapis.com/discovery/v1/apis/calendar/v3/rest
DEBUG:urllib3.util.retry:Converted retries value: 3 -> Retry(total=3, connect=None, read=None, redirect=None, status=None)
DEBUG:urllib3.connectionpool:Starting new HTTPS connection (1): www.googleapis.com:443
DEBUG:urllib3.connectionpool:https://www.googleapis.com:443 "GET /drive/v3/files?q=mimeType%3D%22application%2Fvnd.google-apps.spreadsheet%22+and+name+%3D+%22Nexus+Recording+Schedule+-+Master%22&pageSize=1000&supportsAllDrives=True&includeItemsFromAllDrives=True HTTP/1.1" 200 None
DEBUG:urllib3.connectionpool:Starting new HTTPS connection (1): sheets.googleapis.com:443
DEBUG:urllib3.connectionpool:https://sheets.googleapis.com:443 "GET /v4/spreadsheets/15-sqH2xXxN2Oq-VPR-Ei7u9aUIqImjEMFieo32gd1BQ?includeGridData=false HTTP/1.1" 200 None
DEBUG:googleapiclient.discovery:URL being requested: GET https://www.googleapis.com/calendar/v3/users/me/calendarList?alt=json
WARNING:googleapiclient.discovery_cache:file_cache is unavailable when using oauth2client >= 4.0.0 or google-auth
Traceback (most recent call last):
  File "C:\Users\the real sauce boss\AppData\Local\Programs\Python\Python37-32\lib\site-packages\googleapiclient\discovery_cache\file_cache.py", line 33, in <module>
    from oauth2client.contrib.locked_file import LockedFile
ModuleNotFoundError: No module named 'oauth2client'

During handling of the above exception, another exception occurred:

Traceback (most recent call last):
  File "C:\Users\the real sauce boss\AppData\Local\Programs\Python\Python37-32\lib\site-packages\googleapiclient\discovery_cache\file_cache.py", line 37, in <module>
    from oauth2client.locked_file import LockedFile
ModuleNotFoundError: No module named 'oauth2client'

During handling of the above exception, another exception occurred:

Traceback (most recent call last):
  File "C:\Users\the real sauce boss\AppData\Local\Programs\Python\Python37-32\lib\site-packages\googleapiclient\discovery_cache\__init__.py", line 44, in autodetect
    from . import file_cache
  File "C:\Users\the real sauce boss\AppData\Local\Programs\Python\Python37-32\lib\site-packages\googleapiclient\discovery_cache\file_cache.py", line 41, in <module>
    "file_cache is unavailable when using oauth2client >= 4.0.0 or google-auth"
ImportError: file_cache is unavailable when using oauth2client >= 4.0.0 or google-auth
DEBUG:googleapiclient.discovery:URL being requested: GET https://www.googleapis.com/discovery/v1/apis/sheets/v4/rest
DEBUG:googleapiclient.discovery:URL being requested: GET https://sheets.googleapis.com/v4/spreadsheets/15-sqH2xXxN2Oq-VPR-Ei7u9aUIqImjEMFieo32gd1BQ/values/1-Approve%20Courses-Instructors-DropDown%20Menus%21N2%3AAN799?alt=json
WARNING:googleapiclient.discovery_cache:file_cache is unavailable when using oauth2client >= 4.0.0 or google-auth
Traceback (most recent call last):
  File "C:\Users\the real sauce boss\AppData\Local\Programs\Python\Python37-32\lib\site-packages\googleapiclient\discovery_cache\file_cache.py", line 33, in <module>
    from oauth2client.contrib.locked_file import LockedFile
ModuleNotFoundError: No module named 'oauth2client'

During handling of the above exception, another exception occurred:

Traceback (most recent call last):
  File "C:\Users\the real sauce boss\AppData\Local\Programs\Python\Python37-32\lib\site-packages\googleapiclient\discovery_cache\file_cache.py", line 37, in <module>
    from oauth2client.locked_file import LockedFile
ModuleNotFoundError: No module named 'oauth2client'

During handling of the above exception, another exception occurred:

Traceback (most recent call last):
  File "C:\Users\the real sauce boss\AppData\Local\Programs\Python\Python37-32\lib\site-packages\googleapiclient\discovery_cache\__init__.py", line 44, in autodetect
    from . import file_cache
  File "C:\Users\the real sauce boss\AppData\Local\Programs\Python\Python37-32\lib\site-packages\googleapiclient\discovery_cache\file_cache.py", line 41, in <module>
    "file_cache is unavailable when using oauth2client >= 4.0.0 or google-auth"
ImportError: file_cache is unavailable when using oauth2client >= 4.0.0 or google-auth
DEBUG:googleapiclient.discovery:URL being requested: GET https://www.googleapis.com/discovery/v1/apis/calendar/v3/rest
DEBUG:urllib3.util.retry:Converted retries value: 3 -> Retry(total=3, connect=None, read=None, redirect=None, status=None)
DEBUG:urllib3.connectionpool:Starting new HTTPS connection (1): www.googleapis.com:443
DEBUG:urllib3.connectionpool:https://www.googleapis.com:443 "GET /drive/v3/files?q=mimeType%3D%22application%2Fvnd.google-apps.spreadsheet%22+and+name+%3D+%22Nexus+Recording+Schedule+-+Master%22&pageSize=1000&supportsAllDrives=True&includeItemsFromAllDrives=True HTTP/1.1" 200 None
DEBUG:urllib3.connectionpool:Starting new HTTPS connection (1): sheets.googleapis.com:443
DEBUG:urllib3.connectionpool:https://sheets.googleapis.com:443 "GET /v4/spreadsheets/15-sqH2xXxN2Oq-VPR-Ei7u9aUIqImjEMFieo32gd1BQ?includeGridData=false HTTP/1.1" 200 None
DEBUG:googleapiclient.discovery:URL being requested: GET https://www.googleapis.com/calendar/v3/users/me/calendarList?alt=json
WARNING:googleapiclient.discovery_cache:file_cache is unavailable when using oauth2client >= 4.0.0 or google-auth
Traceback (most recent call last):
  File "C:\Users\the real sauce boss\AppData\Local\Programs\Python\Python37-32\lib\site-packages\googleapiclient\discovery_cache\file_cache.py", line 33, in <module>
    from oauth2client.contrib.locked_file import LockedFile
ModuleNotFoundError: No module named 'oauth2client'

During handling of the above exception, another exception occurred:

Traceback (most recent call last):
  File "C:\Users\the real sauce boss\AppData\Local\Programs\Python\Python37-32\lib\site-packages\googleapiclient\discovery_cache\file_cache.py", line 37, in <module>
    from oauth2client.locked_file import LockedFile
ModuleNotFoundError: No module named 'oauth2client'

During handling of the above exception, another exception occurred:

Traceback (most recent call last):
  File "C:\Users\the real sauce boss\AppData\Local\Programs\Python\Python37-32\lib\site-packages\googleapiclient\discovery_cache\__init__.py", line 44, in autodetect
    from . import file_cache
  File "C:\Users\the real sauce boss\AppData\Local\Programs\Python\Python37-32\lib\site-packages\googleapiclient\discovery_cache\file_cache.py", line 41, in <module>
    "file_cache is unavailable when using oauth2client >= 4.0.0 or google-auth"
ImportError: file_cache is unavailable when using oauth2client >= 4.0.0 or google-auth
DEBUG:googleapiclient.discovery:URL being requested: GET https://www.googleapis.com/discovery/v1/apis/sheets/v4/rest
DEBUG:googleapiclient.discovery:URL being requested: GET https://sheets.googleapis.com/v4/spreadsheets/15-sqH2xXxN2Oq-VPR-Ei7u9aUIqImjEMFieo32gd1BQ/values/1-Approve%20Courses-Instructors-DropDown%20Menus%21N2%3AAN799?alt=json
WARNING:googleapiclient.discovery_cache:file_cache is unavailable when using oauth2client >= 4.0.0 or google-auth
Traceback (most recent call last):
  File "C:\Users\the real sauce boss\AppData\Local\Programs\Python\Python37-32\lib\site-packages\googleapiclient\discovery_cache\file_cache.py", line 33, in <module>
    from oauth2client.contrib.locked_file import LockedFile
ModuleNotFoundError: No module named 'oauth2client'

During handling of the above exception, another exception occurred:

Traceback (most recent call last):
  File "C:\Users\the real sauce boss\AppData\Local\Programs\Python\Python37-32\lib\site-packages\googleapiclient\discovery_cache\file_cache.py", line 37, in <module>
    from oauth2client.locked_file import LockedFile
ModuleNotFoundError: No module named 'oauth2client'

During handling of the above exception, another exception occurred:

Traceback (most recent call last):
  File "C:\Users\the real sauce boss\AppData\Local\Programs\Python\Python37-32\lib\site-packages\googleapiclient\discovery_cache\__init__.py", line 44, in autodetect
    from . import file_cache
  File "C:\Users\the real sauce boss\AppData\Local\Programs\Python\Python37-32\lib\site-packages\googleapiclient\discovery_cache\file_cache.py", line 41, in <module>
    "file_cache is unavailable when using oauth2client >= 4.0.0 or google-auth"
ImportError: file_cache is unavailable when using oauth2client >= 4.0.0 or google-auth
DEBUG:googleapiclient.discovery:URL being requested: GET https://www.googleapis.com/discovery/v1/apis/calendar/v3/rest
DEBUG:urllib3.util.retry:Converted retries value: 3 -> Retry(total=3, connect=None, read=None, redirect=None, status=None)
DEBUG:urllib3.connectionpool:Starting new HTTPS connection (1): www.googleapis.com:443
DEBUG:urllib3.connectionpool:https://www.googleapis.com:443 "GET /drive/v3/files?q=mimeType%3D%22application%2Fvnd.google-apps.spreadsheet%22+and+name+%3D+%22Nexus+Recording+Schedule+-+Master%22&pageSize=1000&supportsAllDrives=True&includeItemsFromAllDrives=True HTTP/1.1" 200 None
DEBUG:urllib3.connectionpool:Starting new HTTPS connection (1): sheets.googleapis.com:443
DEBUG:urllib3.connectionpool:https://sheets.googleapis.com:443 "GET /v4/spreadsheets/15-sqH2xXxN2Oq-VPR-Ei7u9aUIqImjEMFieo32gd1BQ?includeGridData=false HTTP/1.1" 200 None
DEBUG:googleapiclient.discovery:URL being requested: GET https://www.googleapis.com/calendar/v3/users/me/calendarList?alt=json
WARNING:googleapiclient.discovery_cache:file_cache is unavailable when using oauth2client >= 4.0.0 or google-auth
Traceback (most recent call last):
  File "C:\Users\the real sauce boss\AppData\Local\Programs\Python\Python37-32\lib\site-packages\googleapiclient\discovery_cache\file_cache.py", line 33, in <module>
    from oauth2client.contrib.locked_file import LockedFile
ModuleNotFoundError: No module named 'oauth2client'

During handling of the above exception, another exception occurred:

Traceback (most recent call last):
  File "C:\Users\the real sauce boss\AppData\Local\Programs\Python\Python37-32\lib\site-packages\googleapiclient\discovery_cache\file_cache.py", line 37, in <module>
    from oauth2client.locked_file import LockedFile
ModuleNotFoundError: No module named 'oauth2client'

During handling of the above exception, another exception occurred:

Traceback (most recent call last):
  File "C:\Users\the real sauce boss\AppData\Local\Programs\Python\Python37-32\lib\site-packages\googleapiclient\discovery_cache\__init__.py", line 44, in autodetect
    from . import file_cache
  File "C:\Users\the real sauce boss\AppData\Local\Programs\Python\Python37-32\lib\site-packages\googleapiclient\discovery_cache\file_cache.py", line 41, in <module>
    "file_cache is unavailable when using oauth2client >= 4.0.0 or google-auth"
ImportError: file_cache is unavailable when using oauth2client >= 4.0.0 or google-auth
DEBUG:googleapiclient.discovery:URL being requested: GET https://www.googleapis.com/discovery/v1/apis/sheets/v4/rest
DEBUG:googleapiclient.discovery:URL being requested: GET https://sheets.googleapis.com/v4/spreadsheets/15-sqH2xXxN2Oq-VPR-Ei7u9aUIqImjEMFieo32gd1BQ/values/1-Approve%20Courses-Instructors-DropDown%20Menus%21N2%3AAN799?alt=json
WARNING:googleapiclient.discovery_cache:file_cache is unavailable when using oauth2client >= 4.0.0 or google-auth
Traceback (most recent call last):
  File "C:\Users\the real sauce boss\AppData\Local\Programs\Python\Python37-32\lib\site-packages\googleapiclient\discovery_cache\file_cache.py", line 33, in <module>
    from oauth2client.contrib.locked_file import LockedFile
ModuleNotFoundError: No module named 'oauth2client'

During handling of the above exception, another exception occurred:

Traceback (most recent call last):
  File "C:\Users\the real sauce boss\AppData\Local\Programs\Python\Python37-32\lib\site-packages\googleapiclient\discovery_cache\file_cache.py", line 37, in <module>
    from oauth2client.locked_file import LockedFile
ModuleNotFoundError: No module named 'oauth2client'

During handling of the above exception, another exception occurred:

Traceback (most recent call last):
  File "C:\Users\the real sauce boss\AppData\Local\Programs\Python\Python37-32\lib\site-packages\googleapiclient\discovery_cache\__init__.py", line 44, in autodetect
    from . import file_cache
  File "C:\Users\the real sauce boss\AppData\Local\Programs\Python\Python37-32\lib\site-packages\googleapiclient\discovery_cache\file_cache.py", line 41, in <module>
    "file_cache is unavailable when using oauth2client >= 4.0.0 or google-auth"
ImportError: file_cache is unavailable when using oauth2client >= 4.0.0 or google-auth
DEBUG:googleapiclient.discovery:URL being requested: GET https://www.googleapis.com/discovery/v1/apis/calendar/v3/rest
DEBUG:urllib3.util.retry:Converted retries value: 3 -> Retry(total=3, connect=None, read=None, redirect=None, status=None)
DEBUG:urllib3.connectionpool:Starting new HTTPS connection (1): www.googleapis.com:443
DEBUG:urllib3.connectionpool:https://www.googleapis.com:443 "GET /drive/v3/files?q=mimeType%3D%22application%2Fvnd.google-apps.spreadsheet%22+and+name+%3D+%22Nexus+Recording+Schedule+-+Master%22&pageSize=1000&supportsAllDrives=True&includeItemsFromAllDrives=True HTTP/1.1" 200 None
DEBUG:urllib3.connectionpool:Starting new HTTPS connection (1): sheets.googleapis.com:443
DEBUG:urllib3.connectionpool:https://sheets.googleapis.com:443 "GET /v4/spreadsheets/15-sqH2xXxN2Oq-VPR-Ei7u9aUIqImjEMFieo32gd1BQ?includeGridData=false HTTP/1.1" 200 None
DEBUG:googleapiclient.discovery:URL being requested: GET https://www.googleapis.com/calendar/v3/users/me/calendarList?alt=json
WARNING:googleapiclient.discovery_cache:file_cache is unavailable when using oauth2client >= 4.0.0 or google-auth
Traceback (most recent call last):
  File "C:\Users\the real sauce boss\AppData\Local\Programs\Python\Python37-32\lib\site-packages\googleapiclient\discovery_cache\file_cache.py", line 33, in <module>
    from oauth2client.contrib.locked_file import LockedFile
ModuleNotFoundError: No module named 'oauth2client'

During handling of the above exception, another exception occurred:

Traceback (most recent call last):
  File "C:\Users\the real sauce boss\AppData\Local\Programs\Python\Python37-32\lib\site-packages\googleapiclient\discovery_cache\file_cache.py", line 37, in <module>
    from oauth2client.locked_file import LockedFile
ModuleNotFoundError: No module named 'oauth2client'

During handling of the above exception, another exception occurred:

Traceback (most recent call last):
  File "C:\Users\the real sauce boss\AppData\Local\Programs\Python\Python37-32\lib\site-packages\googleapiclient\discovery_cache\__init__.py", line 44, in autodetect
    from . import file_cache
  File "C:\Users\the real sauce boss\AppData\Local\Programs\Python\Python37-32\lib\site-packages\googleapiclient\discovery_cache\file_cache.py", line 41, in <module>
    "file_cache is unavailable when using oauth2client >= 4.0.0 or google-auth"
ImportError: file_cache is unavailable when using oauth2client >= 4.0.0 or google-auth
DEBUG:googleapiclient.discovery:URL being requested: GET https://www.googleapis.com/discovery/v1/apis/sheets/v4/rest
DEBUG:googleapiclient.discovery:URL being requested: GET https://sheets.googleapis.com/v4/spreadsheets/15-sqH2xXxN2Oq-VPR-Ei7u9aUIqImjEMFieo32gd1BQ/values/1-Approve%20Courses-Instructors-DropDown%20Menus%21N2%3AAN799?alt=json
WARNING:googleapiclient.discovery_cache:file_cache is unavailable when using oauth2client >= 4.0.0 or google-auth
Traceback (most recent call last):
  File "C:\Users\the real sauce boss\AppData\Local\Programs\Python\Python37-32\lib\site-packages\googleapiclient\discovery_cache\file_cache.py", line 33, in <module>
    from oauth2client.contrib.locked_file import LockedFile
ModuleNotFoundError: No module named 'oauth2client'

During handling of the above exception, another exception occurred:

Traceback (most recent call last):
  File "C:\Users\the real sauce boss\AppData\Local\Programs\Python\Python37-32\lib\site-packages\googleapiclient\discovery_cache\file_cache.py", line 37, in <module>
    from oauth2client.locked_file import LockedFile
ModuleNotFoundError: No module named 'oauth2client'

During handling of the above exception, another exception occurred:

Traceback (most recent call last):
  File "C:\Users\the real sauce boss\AppData\Local\Programs\Python\Python37-32\lib\site-packages\googleapiclient\discovery_cache\__init__.py", line 44, in autodetect
    from . import file_cache
  File "C:\Users\the real sauce boss\AppData\Local\Programs\Python\Python37-32\lib\site-packages\googleapiclient\discovery_cache\file_cache.py", line 41, in <module>
    "file_cache is unavailable when using oauth2client >= 4.0.0 or google-auth"
ImportError: file_cache is unavailable when using oauth2client >= 4.0.0 or google-auth
DEBUG:googleapiclient.discovery:URL being requested: GET https://www.googleapis.com/discovery/v1/apis/calendar/v3/rest
DEBUG:urllib3.util.retry:Converted retries value: 3 -> Retry(total=3, connect=None, read=None, redirect=None, status=None)
DEBUG:urllib3.connectionpool:Starting new HTTPS connection (1): www.googleapis.com:443
DEBUG:urllib3.connectionpool:https://www.googleapis.com:443 "GET /drive/v3/files?q=mimeType%3D%22application%2Fvnd.google-apps.spreadsheet%22+and+name+%3D+%22Nexus+Recording+Schedule+-+Master%22&pageSize=1000&supportsAllDrives=True&includeItemsFromAllDrives=True HTTP/1.1" 200 None
DEBUG:urllib3.connectionpool:Starting new HTTPS connection (1): sheets.googleapis.com:443
DEBUG:urllib3.connectionpool:https://sheets.googleapis.com:443 "GET /v4/spreadsheets/15-sqH2xXxN2Oq-VPR-Ei7u9aUIqImjEMFieo32gd1BQ?includeGridData=false HTTP/1.1" 200 None
DEBUG:googleapiclient.discovery:URL being requested: GET https://www.googleapis.com/calendar/v3/users/me/calendarList?alt=json
WARNING:googleapiclient.discovery_cache:file_cache is unavailable when using oauth2client >= 4.0.0 or google-auth
Traceback (most recent call last):
  File "C:\Users\the real sauce boss\AppData\Local\Programs\Python\Python37-32\lib\site-packages\googleapiclient\discovery_cache\file_cache.py", line 33, in <module>
    from oauth2client.contrib.locked_file import LockedFile
ModuleNotFoundError: No module named 'oauth2client'

During handling of the above exception, another exception occurred:

Traceback (most recent call last):
  File "C:\Users\the real sauce boss\AppData\Local\Programs\Python\Python37-32\lib\site-packages\googleapiclient\discovery_cache\file_cache.py", line 37, in <module>
    from oauth2client.locked_file import LockedFile
ModuleNotFoundError: No module named 'oauth2client'

During handling of the above exception, another exception occurred:

Traceback (most recent call last):
  File "C:\Users\the real sauce boss\AppData\Local\Programs\Python\Python37-32\lib\site-packages\googleapiclient\discovery_cache\__init__.py", line 44, in autodetect
    from . import file_cache
  File "C:\Users\the real sauce boss\AppData\Local\Programs\Python\Python37-32\lib\site-packages\googleapiclient\discovery_cache\file_cache.py", line 41, in <module>
    "file_cache is unavailable when using oauth2client >= 4.0.0 or google-auth"
ImportError: file_cache is unavailable when using oauth2client >= 4.0.0 or google-auth
DEBUG:googleapiclient.discovery:URL being requested: GET https://www.googleapis.com/discovery/v1/apis/sheets/v4/rest
DEBUG:googleapiclient.discovery:URL being requested: GET https://sheets.googleapis.com/v4/spreadsheets/15-sqH2xXxN2Oq-VPR-Ei7u9aUIqImjEMFieo32gd1BQ/values/1-Approve%20Courses-Instructors-DropDown%20Menus%21N2%3AAN799?alt=json
